Workbook

Sheet GCM
B1: General Consumer Market (GCM) - GRPs A18-49
B2: Revision 1 (as of 11.12.2025)
B3: 2026 US Media Mix Calendar | C3: January | G3: February | K3: March | P3: April | T3: May | X3: June | AC3: July | AG3: August | AL3: September | AP3: October | AT3: November | AY3: December
C4: 5 | D4: 12 | E4: 19 | F4: 26 | G4: 2 | H4: 9 | I4: 16 | J4: 23 | K4: 2 | L4: 9 | M4: 16 | N4: 23 | O4: 30 | P4: 6 | Q4: 13 | R4: 20 | S4: 27 | T4: 4 | U4: 11 | V4: 18 | W4: 25 | X4: 1 | Y4: 8 | Z4: 15 | AA4: 22 | AB4: 29 | AC4: 6 | AD4: 13 | AE4: 20 | AF4: 27 | AG4: 3 | AH4: 10 | AI4: 17 | AJ4: 24 | AK4: 31 | AL4: 7 | AM4: 14 | AN4: 21 | AO4: 28 | AP4: 5 | AQ4: 12 | AR4: 19 | AS4: 26 | AT4: 2 | AU4: 9 | AV4: 16 | AW4: 23 | AX4: 30 | AY4: 7 | AZ4: 14 | BA4: 21 | BB4: 28
B6: RELEVANCE
O7: Brand Relevance | Y7: Brand Relevance | AX7: Brand Relevance
O8: =SUM(R9:R14) -> 730.1812 | Y8: =SUM(AD9:AD14) -> 1070.6636 | AX8: =SUM(AZ9:AZ14) -> 615.6613
O9: Gaming | R9: 92.666 | Y9: Gaming | AD9: 18 | AX9: Gaming | AZ9: 12
O10: Linear Video | R10: 84.9152 | Y10: Linear Video | AD10: 184.0098 | AX10: Linear Video | AZ10: 216.6613
O11: Partnership | R11: 33 | Y11: Partnership | AD11: 24 | AX11: Partnership | AZ11: 18
O12: POD/Dig Vid | R12: 135.6 | Y12: POD/Dig Vid | AD12: 97.055 | AX12: POD/Dig Vid | AZ12: 69
O13: Social | R13: 290 | Y13: Social | AD13: 636 | AX13: Social | AZ13: 240
O14: Streaming Audio | R14: 94 | Y14: Streaming Audio | AD14: 111.5988 | AX14: Streaming Audio | AZ14: 60
O15: 182.5453 | P15: 182.5453 | Q15: 182.5453 | R15: 182.5453 | Y15: 180.7741 | Z15: 180.8717 | AA15: 180.8717 | AB15: 176.0487 | AC15: 176.0487 | AD15: 176.0487 | AX15: 205.2205 | AY15: 205.2204 | AZ15: 205.2204
X17: GCM TBI: LGBTQ+ | AO17: GCM TBI: LGBTQ+
X18: =SUM(AA19:AA21) -> 60 | AO18: =SUM(AR19:AR21) -> 60
X19: Partnership | AA19: 12 | AO19: Partnership | AR19: 12
X20: Social | AA20: 42 | AO20: Social | AR20: 42
X21: Streaming Audio | AA21: 6 | AO21: Streaming Audio | AR21: 6
X22: 15 | Y22: 15 | Z22: 15 | AA22: 15 | AO22: 15 | AP22: 15 | AQ22: 15 | AR22: 15
BC23: =SUM(C8:BB8, C18:BB18) -> 2536.5061
B25: CORE
L26: Big Arch | AE26: Breakfast (July) | AT26: Breakfast (Nov)
L27: =SUM(N28:N32) -> 570.90259 | AE27: =SUM(AG28:AG33) -> 495 | AT27: =SUM(AV28:AV33) -> 538.88875
L28: Gaming | N28: 13.174424 | AE28: Gaming | AG28: 9.9 | AT28: Gaming | AV28: 9.9
L29: Linear Video | N29: 101.19 | AE29: Linear Video | AG29: 49.5 | AT29: Linear Video | AV29: 152.78875
L30: POD/Dig Vid | N30: 104.26323 | AE30: Partnership | AG30: 9.9 | AT30: Partnership | AV30: 9.9
L31: Social | N31: 259.875 | AE31: POD/Dig Vid | AG31: 94.05 | AT31: POD/Dig Vid | AV31: 84.15
L32: Streaming Audio | N32: 92.399937 | AE32: Social | AG32: 222.75 | AT32: Social | AV32: 198
L33: 190.30086 | M33: 190.30086 | N33: 190.30086 | AE33: Streaming Audio | AG33: 108.9 | AT33: Streaming Audio | AV33: 84.15
AE34: 165 | AF34: 165 | AG34: 165 | AT34: 179.62958 | AU34: 179.62958 | AV34: 179.62958
G36: Chicken | AF36: Chicken
G37: =SUM(J38:J43) -> 702.43776 | AF37: =SUM(AI38:AI43) -> 807.10034
G38: Gaming | J38: 16 | AF38: Gaming | AI38: 16.142471
G39: Linear Video | J39: 121.55029 | AF39: Linear Video | AI39: 39.552
G40: Partnership | J40: 34.13252 | AF40: Partnership | AI40: 16.142471
G41: POD/Dig Vid | J41: 128.51503 | AF41: POD/Dig Vid | AI41: 161.42471
G42: Social | J42: 314.29217 | AF42: Social | AI42: 444.69893
G43: Streaming Audio | J43: 87.947752 | AF43: Streaming Audio | AI43: 129.13977
G44: 175.60944 | H44: 175.60944 | I44: 175.60944 | J44: 175.60944 | AF44: 201.77509 | AG44: 201.77509 | AH44: 201.77509 | AI44: 201.77509
...

Sheet HCM
B1: Hispanic Consumer Market (HCM) - GRPs HA18-49
B2: =+GCM!B2 -> Revision 1 (as of 11.12.2025)
B3: =+GCM!B3 -> 2026 US Media Mix Calendar | C3: Dec | D3: January | H3: February | L3: March | Q3: April | U3: May | Y3: June | AD3: July | AH3: August | AM3: September | AQ3: October | AU3: November | AZ3: December
C4: 29 | D4: 5 | E4: 12 | F4: 19 | G4: 26 | H4: 2 | I4: 9 | J4: 16 | K4: 23 | L4: 2 | M4: 9 | N4: 16 | O4: 23 | P4: 30 | Q4: 6 | R4: 13 | S4: 20 | T4: 27 | U4: 4 | V4: 11 | W4: 18 | X4: 25 | Y4: 1 | Z4: 8 | AA4: 15 | AB4: 22 | AC4: 29 | AD4: 6 | AE4: 13 | AF4: 20 | AG4: 27 | AH4: 3 | AI4: 10 | AJ4: 17 | AK4: 24 | AL4: 31 | AM4: 7 | AN4: 14 | AO4: 21 | AP4: 28 | AQ4: 5 | AR4: 12 | AS4: 19 | AT4: 26 | AU4: 2 | AV4: 9 | AW4: 16 | AX4: 23 | AY4: 30 | AZ4: 7 | BA4: 14 | BB4: 21 | BC4: 28
B6: RELEVANCE
P7: Brand Relevance | Z7: Brand Relevance | AY7: Brand Relevance
P8: =SUM(S9:S14) -> 1479.6218 | Z8: =SUM(AE9:AE15) -> 2730.936 | AY8: =SUM(BA9:BA14) -> 893.09661
P9: Gaming | S9: 28.034225 | Z9: Gaming | AE9: 91.2 | AY9: Gaming | BA9: 27.3
P10: Linear Video | S10: 495.58048 | Z10: Linear Video | AE10: 235.17531 | AY10: Linear Video | BA10: 113.09661
P11: Partnership | S11: 92.154869 | Z11: Partnership | AE11: 301.86207 | AY11: Partnership | BA11: 70.2
P12: POD/Dig Vid | S12: 262.45242 | Z12: POD/Dig Vid | AE12: 454.00212 | AY12: POD/Dig Vid | BA12: 202.8
P13: Social | S13: 449.95898 | Z13: Radio | AE13: 159.6 | AY13: Social | BA13: 362.7
P14: Streaming Audio | S14: 151.44079 | Z14: Social | AE14: 1071.6 | AY14: Streaming Audio | BA14: 117
P15: 328.80484 | Q15: 383.60564 | R15: 383.60564 | S15: 383.60564 | Z15: Streaming Audio | AE15: 417.49648 | AY15: 267.92898 | AZ15: 312.58381 | BA15: 312.58381
Z16: 406.10335 | AA16: 473.78724 | AB16: 473.78724 | AC16: 459.08604 | AD16: 459.08604 | AE16: 459.08604
C18: TBI: Hacer | AT18: TBI: Hacer
C19: =SUM(J20:J27) -> 644.7687 | AT19: =SUM(BB20:BB27) -> 874.52122
C20: Display | J20: 14.478362 | AT20: Display | BB20: 16.74
C21: Linear Video | J21: 45.708792 | AT21: Linear Video | BB21: 81.04522
C22: Partnership | J22: 29.96591 | AT22: Partnership | BB22: 50.22
C23: POD/Dig Vid | J23: 86.550643 | AT23: POD/Dig Vid | BB23: 112.995
C24: Radio | J24: 26.625 | AT24: Radio | BB24: 41.85
C25: Search | J25: 1.6260972 | AT25: Search | BB25: 2.511
C26: Social | J26: 388.33693 | AT26: Social | BB26: 410.13
C27: Streaming Audio | J27: 51.476968 | AT27: Streaming Audio | BB27: 159.03
C28: 88.497665 | D28: 88.497665 | E28: 88.497665 | F28: 88.497665 | G28: 88.497665 | H28: 88.497665 | I28: 88.497665 | J28: 25.285047 | AT28: 97.169025 | AU28: 97.169025 | AV28: 97.169025 | AW28: 97.169025 | AX28: 97.169025 | AY28: 97.169025 | AZ28: 97.169025 | BA28: 97.169025 | BB28: 97.169025
BD29: =SUM(C8:BC8,C19:BC19) -> 6622.9443
B31: CORE
M32: Big Arch | AF32: Breakfast (July) | AU32: Breakfast (Nov)
M33: =SUM(O34:O40) -> 1314.5272 | AF33: =SUM(AH34:AH39) -> 1049.8099 | AU33: =SUM(AW34:AW39) -> 1055.5361
M34: Gaming | O34: 59.29 | AF34: Linear Video | AH34: 114.72443 | AU34: Linear Video | AW34: 228.33895
M35: Linear Video | O35: 518.73621 | AF35: Partnership | AH35: 128.51544 | AU35: Partnership | AW35: 146.79905
M36: Partnership | O36: 5.75 | AF36: POD/Dig Vid | AH36: 127.15097 | AU36: POD/Dig Vid | AW36: 131.0355
M37: POD/Dig Vid | O37: 173.95097 | AF37: Radio | AH37: 84 | AU37: Radio | AW37: 84
M38: Radio | O38: 28.8 | AF38: Social | AH38: 503.01911 | AU38: Social | AW38: 352.8
M39: Social | O39: 403.2 | AF39: Streaming Audio | AH39: 92.4 | AU39: Streaming Audio | AW39: 112.56263
M40: Streaming Audio | O40: 124.8 | AF40: 349.93665 | AG40: 349.93665 | AH40: 349.93665 | AU40: 343.83256 | AV40: 367.87102 | AW40: 343.83256
M41: 444.10636 | N41: 436.69895 | O41: 433.73599
H43: Chicken | AG43: Chicken
H44: =SUM(K45:K50) -> 1456.0392 | AG44: =SUM(AJ45:AJ51) -> 1555.3783
...

Sheet AACM
B1: African American Consumer Market (AACM) - GRPs AA18-49
B2: =+GCM!B2 -> Revision 1 (as of 11.12.2025)
B3: =+GCM!B3 -> 2026 US Media Mix Calendar | C3: January | G3: February | K3: March | P3: April | T3: May | X3: June | AC3: July | AG3: August | AL3: September | AP3: October | AT3: November | AY3: December
C4: 5 | D4: 12 | E4: 19 | F4: 26 | G4: 2 | H4: 9 | I4: 16 | J4: 23 | K4: 2 | L4: 9 | M4: 16 | N4: 23 | O4: 30 | P4: 6 | Q4: 13 | R4: 20 | S4: 27 | T4: 4 | U4: 11 | V4: 18 | W4: 25 | X4: 1 | Y4: 8 | Z4: 15 | AA4: 22 | AB4: 29 | AC4: 6 | AD4: 13 | AE4: 20 | AF4: 27 | AG4: 3 | AH4: 10 | AI4: 17 | AJ4: 24 | AK4: 31 | AL4: 7 | AM4: 14 | AN4: 21 | AO4: 28 | AP4: 5 | AQ4: 12 | AR4: 19 | AS4: 26 | AT4: 2 | AU4: 9 | AV4: 16 | AW4: 23 | AX4: 30 | AY4: 7 | AZ4: 14 | BA4: 21 | BB4: 28
B6: RELEVANCE
O7: Brand Relevance | Y7: Brand Relevance | AX7: Brand Relevance
O8: =SUM(R9:R14) -> 1174.058 | Y8: =SUM(AD9:AD14) -> 1770.2244 | AX8: =SUM(AZ9:AZ13) -> 810
O9: Gaming | R9: 66 | Y9: Gaming | AD9: 102 | AX9: Gaming | AZ9: 54
O10: Linear Video | R10: 60.2 | Y10: Linear Video | AD10: 105.0489 | AX10: Partnership | AZ10: 85.5
O11: Partnership | R11: 126 | Y11: Partnership | AD11: 126 | AX11: POD/Dig Vid | AZ11: 148.5
O12: POD/Dig Vid | R12: 204 | Y12: POD/Dig Vid | AD12: 357.1755 | AX12: Social | AZ12: 405
O13: Social | R13: 486 | Y13: Social | AD13: 774 | AX13: Streaming Audio | AZ13: 117
O14: Streaming Audio | R14: 231.858 | Y14: Streaming Audio | AD14: 306 | AX14: 270 | AY14: 270 | AZ14: 270
O15: 293.5145 | P15: 293.5145 | Q15: 293.5145 | R15: 293.5145 | Y15: 290.0748 | Z15: 290.0748 | AA15: 290.0748 | AB15: 300 | AC15: 300 | AD15: 300
M17: TBI: Scholars | AS17: TBI: Scholars | AX17: TBI: Scholars
M18: =SUM(R19:R24) -> 613.33986 | AS18: =SUM(AV19:AV25) -> 362.4233 | AX18: =SUM(AZ19:AZ25) -> 271.8177
M19: Display | R19: 239.9021 | AS19: Display | AV19: 63 | AX19: Display | AZ19: 47.25
M20: Linear Video | R20: 77.28 | AS20: Linear Video | AV20: 40.48 | AX20: Linear Video | AZ20: 30.3603
M21: POD/Dig Vid | R21: 65.49182 | AS21: Partnership | AV21: 21.6 | AX21: Partnership | AZ21: 16.2
M22: Search | R22: 2 | AS22: POD/Dig Vid | AV22: 59.8 | AX22: POD/Dig Vid | AZ22: 44.85
M23: Social | R23: 128.8243 | AS23: Search | AV23: 1.1432 | AX23: Search | AZ23: 0.8574
M24: Streaming Audio | R24: 99.84164 | AS24: Social | AV24: 118.8 | AX24: Social | AZ24: 89.1
M25: 102.89 | N25: 102.89 | O25: 101.89 | P25: 101.89 | Q25: 101.89 | R25: 101.8901 | AS25: Streaming Audio | AV25: 57.6001 | AX25: Streaming Audio | AZ25: 43.2
AS26: 90.6059 | AT26: 90.6058 | AU26: 90.6058 | AV26: 90.6058 | AX26: 90.6058 | AY26: 90.6058 | AZ26: 90.6061
BC27: =SUM(C8:BB8,C18:BB18) -> 5001.8633
B29: CORE
L30: Big Arch | AE30: Breakfast (July) | AT30: Breakfast (Nov)
L31: =SUM(N32:N36) -> 1090.9319 | AE31: =SUM(AG32:AG37) -> 1109.28 | AT31: =SUM(AV32:AV37) -> 870.3
L32: Gaming | N32: 115.9195 | AE32: Linear Video | AG32: 99 | AT32: Linear Video | AV32: 69.3
L33: Linear Video | N33: 75.6 | AE33: Partnership | AG33: 96 | AT33: Partnership | AV33: 54
L34: POD/Dig Vid | N34: 327.0124 | AE34: POD/Dig Vid | AG34: 264 | AT34: POD/Dig Vid | AV34: 216
L35: Social | N35: 367.2 | AE35: Radio | AG35: 36 | AT35: Radio | AV35: 36
L36: Streaming Audio | N36: 205.2 | AE36: Social | AG36: 416.28 | AT36: Social | AV36: 306
L37: 363.644 | M37: 363.644 | N37: 363.644 | AE37: Streaming Audio | AG37: 198 | AT37: Streaming Audio | AV37: 189
AE38: 369.76 | AF38: 369.76 | AG38: 369.76 | AT38: 290.1 | AU38: 290.1 | AV38: 290.1
G40: Chicken | AF40: Chicken
G41: =SUM(J42:J47) -> 1449.2283 | AF41: =SUM(AI42:AI47) -> 1708.6064
G42: Gaming | J42: 61.81495 | AF42: Gaming | AI42: 91.17635
G43: Linear Video | J43: 167.11 | AF43: Linear Video | AI43: 172.5563
G44: Partnership | J44: 123 | AF44: Partnership | AI44: 216
...

Sheet ACM
B1: Asian Consumer Market (ACM)
B2: =+GCM!B2 -> Revision 1 (as of 11.12.2025)
B3: =+GCM!B3 -> 2026 US Media Mix Calendar | C3: Dec | D3: January | H3: February | L3: March | Q3: April | U3: May | Y3: June | AD3: July | AH3: August | AM3: September | AQ3: October | AU3: November | AZ3: December
C4: 29 | D4: 5 | E4: 12 | F4: 19 | G4: 26 | H4: 2 | I4: 9 | J4: 16 | K4: 23 | L4: 2 | M4: 9 | N4: 16 | O4: 23 | P4: 30 | Q4: 6 | R4: 13 | S4: 20 | T4: 27 | U4: 4 | V4: 11 | W4: 18 | X4: 25 | Y4: 1 | Z4: 8 | AA4: 15 | AB4: 22 | AC4: 29 | AD4: 6 | AE4: 13 | AF4: 20 | AG4: 27 | AH4: 3 | AI4: 10 | AJ4: 17 | AK4: 24 | AL4: 31 | AM4: 7 | AN4: 14 | AO4: 21 | AP4: 28 | AQ4: 5 | AR4: 12 | AS4: 19 | AT4: 26 | AU4: 2 | AV4: 9 | AW4: 16 | AX4: 23 | AY4: 30 | AZ4: 7 | BA4: 14 | BB4: 21 | BC4: 28
B6: RELEVANCE
P7: Brand Relevance | Z7: Brand Relevance | AY7: Brand Relevance
P8: Gaming, Linear Video, Partnership, POD/Dig Video, Social, Streaming Audio | Z8: Gaming, Linear Video, Partnership, POD/Dig Video, Social, Streaming Audio | AY8: Gaming, Linear Video, Partnership, POD/Dig Video, Social, Streaming Audio
C12: TBI: APA Next | AD12: Depth Work TBD | AP12: TBI: APA Next
C13: Linear Video, POD/Dig Video, Social, Streaming Audio | AD13: Linear Video, Partnership, POD/Dig Video, Social, Streaming Audio | AP13: Linear Video, Partnership, POD/Dig Video, Social, Streaming Audio
B18: CORE
M19: Big Arch | AF19: Breakfast (July) | AU19: Breakfast (Nov)
M20: Gaming, Linear Video, POD/Dig Video, Social, Streaming Audio | AF20: Gaming, Linear Video, Partnership, POD/Dig Video, Social, Streaming Audio | AU20: Gaming, Linear Video, Partnership, POD/Dig Video, Social, Streaming Audio
H24: Chicken | AG24: Chicken
H25: Gaming, Linear Video, Partnership, POD/Dig Video, Social, Streaming Audio | AG25: Gaming, Linear Video, Partnership, POD/Dig Video, Social, Streaming Audio
B30: BEVERAGE
V31: Beverage | AK31: Beverage | AV31: Beverage
V32: Gaming, Linear Video, Partnership, POD/Dig Video, Social, Streaming Audio | AK32: Gaming, Linear Video, Partnership, POD/Dig Video, Social, Streaming Audio | AV32: Gaming, Linear Video, Partnership, POD/Dig Video, Social, Streaming Audio
B37: VALUE FOR MONEY
D38: McValue Menu 1 (Jan) | J38: McValue Menu 2 (Feb) | T38: McValue Menu 3 (Apr) | AM38: McValue Menu 4 (Sep) | AQ38: Monopoly
D39: Linear Video, POD/Dig Video, Social, Streaming Audio | J39: Gaming, Linear Video, POD/Dig Video, Social, Streaming Audio | T39: Gaming, Linear Video, POD/Dig Video, Social, Streaming Audio | AM39: Gaming, Linear Video, POD/Dig Video, Social, Streaming Audio | AQ39: Gaming, Linear Video, Partnership, POD/Dig Video, Social, Streaming Audio
C43: 3PO DELIVERY
B45: TOTAL
