Workbook

Sheet Locations
A1: Location Profile | AZ1: =TODAY() -> 46266 | BA1: Food Cost - Inventory Routines and Mobile App Setup | BL1: Last Revised - 03/24/26 4:33 PM
A2: Location Name | B2: Owner/Operator | C2: OperatorEmail | D2: OperatorEmail2 | E2: Organization | F2: Supervisor | G2: Effective Date | H2: SupEmail | I2: GM | J2: GMEmail | K2: Email Domain | L2: Users | M2: MDP Email | N2: MDP Password | O2: LocNameForDisplay | P2: Address | Q2: Inventory D/W/M Setup Verified | R2: eProduction Settings Updated and Verified | S2: eProduction Verified Date | T2: Weekly Inventory Count Day | U2: FOB Risk Profile | V2: FOB Driver | W2: Controls Risk Profile | X2: Controls Driver | Y2: Primary Counting Manager | Z2: Mobile Inventory App Training Occurred | AA2: Mobile App Training Scheduled | AB2: Martin Brower Delivery Day 1 | AC2: Martin Brower Delivery Day 2 | AD2: Martin Brower Delivery Day 3 | AE2: Store Settings Updated for Inventory | AF2: Scheduling Manager | AG2: Schedule Workshop | AH2: FLH Verified | AI2: Availability Update | AJ2: Skill Levels Updated | AK2: 1st Schedule Week | BA2: Location | BB2: Supervisor | BC2: GM | BD2: Counting Manager | BE2: Time Needed | BF2: Date Scheduled | BG2: Start Time | BH2: RGR Date | BI2: Count Day | BJ2: FOB Risk | BK2: Validity | BL2: Status | BM2: Store Settings Updated for Inventory
A3: 3708 | B3: Ryan Thorley | C3: =LEFT(Table1[[#This Row],[Owner/Operator]], SEARCH(" ", Table1[[#This Row],[Owner/Operator]]) - 1) & "@" & Table1[[#This Row],[Email Domain]] -> Ryan@mcdok.com | E3: MCDOK | F3: Robert Spencer | H3: =LEFT(Table1[[#This Row],[Supervisor]], SEARCH(" ", Table1[[#This Row],[Supervisor]]) - 1) & "@" & Table1[[#This Row],[Email Domain]] -> Robert@mcdok.com | I3: Cinthya Armedariz | J3: =LEFT(Table1[[#This Row],[GM]], SEARCH(" ", Table1[[#This Row],[GM]]) - 1) & "@" & Table1[[#This Row],[Email Domain]] -> Cinthya@mcdok.com | K3: mcdok.com | L3: 461 | M3: ="mcdok.mdp+"&Table1[[#This Row],[Location Name]]&"@gmail.com" -> mcdok.mdp+3708@gmail.com | N3: ="Mcdok.mdp"&Table1[[#This Row],[Location Name]] -> Mcdok.mdp3708 | O3: 3708 - ARDMORE-BROADWAY | P3: 1001 W Broadway, Ardmore, OK, 73401, USA | Q3: Yes | R3: No | T3: Tuesday | U3: =_xlfn.XLOOKUP(Table1[[#This Row],[Location Name]],'Risk Profiles'!$A$18:$A$37,'Risk Profiles'!$B$18:$B$37) -> Medium | V3: =_xlfn.XLOOKUP(Table1[[#This Row],[Location Name]],'Risk Profiles'!$A$18:$A$37,'Risk Profiles'!$C$18:$C$37) -> Within Normal range | W3: =_xlfn.XLOOKUP(Table1[[#This Row],[Location Name]],'Risk Profiles'!$A$18:$A$37,'Risk Profiles'!$D$18:$D$37) -> High | X3: =_xlfn.XLOOKUP(Table1[[#This Row],[Location Name]],'Risk Profiles'!$A$18:$A$37,'Risk Profiles'!$E$18:$E$37) -> T-Red After (0.29%), Cash O/S (0.04%), Overrings (0.58%) | Y3: Cinthya | Z3: Yes | AA3: =_xlfn.XLOOKUP(A3,Table3[Location],Table3[Date Scheduled]) -> 46133 | AB3: Wednesday | AC3: Sunday | AE3: 46128 | AF3: Siara | AG3: 46268 | AH3: Yes | AI3: Yes | AJ3: Yes | AK3: =IFERROR(INDEX('Scheduling Setup'!$L:$L,MATCH($A3,'Scheduling Setup'!$A:$A,0)),"") -> 46274 | BA3: 6972 | BB3: =_xlfn.XLOOKUP($BA3,$A$3:$A$32,$F$3:$F$32) -> Robert Spencer | BC3: =_xlfn.XLOOKUP($BA3,$A$3:$A$32,$I$3:$I$32) -> Nick Rice | BD3: =IF(_xlfn.XLOOKUP($BA3,$A$3:$A$32,$Y$3:$Y$32)="","",_xlfn.XLOOKUP($BA3,$A$3:$A$32,$Y$3:$Y$32)) -> Beth | BF3: 46065 | BH3: =_xlfn.XLOOKUP(Table3[[#This Row],[Location]],Table4[STORE '#],Table4[DATE RGR]) -> 46063 | BI3: =_xlfn.XLOOKUP(Table3[[#This Row],[Location]],Table1[Location Name],Table1[Weekly Inventory Count Day]) -> Thursday | BJ3: =_xlfn.XLOOKUP(Table3[[#This Row],[Location]],Table1[Location Name],Table1[FOB Risk Profile]) -> Medium | BM3: 46128
A4: 5183 | B4: Gary Mornhinweg | C4: =LEFT(Table1[[#This Row],[Owner/Operator]], SEARCH(" ", Table1[[#This Row],[Owner/Operator]]) - 1) & "@" & Table1[[#This Row],[Email Domain]] -> Gary@mcdok.com | E4: MCDOK | F4: Krystiana Langford | H4: =LEFT(Table1[[#This Row],[Supervisor]], SEARCH(" ", Table1[[#This Row],[Supervisor]]) - 1) & "@" & Table1[[#This Row],[Email Domain]] -> Krystiana@mcdok.com | I4: Mukarram Norman | J4: =LEFT(Table1[[#This Row],[GM]], SEARCH(" ", Table1[[#This Row],[GM]]) - 1) & "@" & Table1[[#This Row],[Email Domain]] -> Mukarram@mcdok.com | K4: mcdok.com | L4: 465 | M4: ="mcdok.mdp+"&Table1[[#This Row],[Location Name]]&"@gmail.com" -> mcdok.mdp+5183@gmail.com | N4: ="Mcdok.mdp"&Table1[[#This Row],[Location Name]] -> Mcdok.mdp5183 | O4: 5183 - CHICKASHA-SO 4TH | P4: 2027 S 4th St, Chickasha, OK, 73018, USA | Q4: Yes | R4: No | T4: Thursday | U4: =_xlfn.XLOOKUP(Table1[[#This Row],[Location Name]],'Risk Profiles'!$A$18:$A$37,'Risk Profiles'!$B$18:$B$37) -> Medium | V4: =_xlfn.XLOOKUP(Table1[[#This Row],[Location Name]],'Risk Profiles'!$A$18:$A$37,'Risk Profiles'!$C$18:$C$37) -> Stat Var (1.80%) | W4: =_xlfn.XLOOKUP(Table1[[#This Row],[Location Name]],'Risk Profiles'!$A$18:$A$37,'Risk Profiles'!$D$18:$D$37) -> Medium | X4: =_xlfn.XLOOKUP(Table1[[#This Row],[Location Name]],'Risk Profiles'!$A$18:$A$37,'Risk Profiles'!$E$18:$E$37) -> Cash O/S (0.04%), Discounts (6.57%) | Y4: Mukarram | Z4: Yes | AA4: =_xlfn.XLOOKUP(A4,Table3[Location],Table3[Date Scheduled]) -> 46163 | AB4: Tuesday | AC4: Friday | AE4: 46128 | AF4: Pam | AG4: 46247 | AH4: Yes | AI4: Yes | AJ4: Yes | AK4: =IFERROR(INDEX('Scheduling Setup'!$L:$L,MATCH($A4,'Scheduling Setup'!$A:$A,0)),"") -> 46260 | BA4: 24471 | BB4: =_xlfn.XLOOKUP($BA4,$A$3:$A$32,$F$3:$F$32) -> Robert Spencer | BC4: =_xlfn.XLOOKUP($BA4,$A$3:$A$32,$I$3:$I$32) -> Mystykal Abbey | BD4: =IF(_xlfn.XLOOKUP($BA4,$A$3:$A$32,$Y$3:$Y$32)="","",_xlfn.XLOOKUP($BA4,$A$3:$A$32,$Y$3:$Y$32)) -> Mystikal | BF4: 46086 | BH4: =_xlfn.XLOOKUP(Table3[[#This Row],[Location]],Table4[STORE '#],Table4[DATE RGR]) -> 46309 | BI4: =_xlfn.XLOOKUP(Table3[[#This Row],[Location]],Table1[Location Name],Table1[Weekly Inventory Count Day]) -> Thursday | BJ4: =_xlfn.XLOOKUP(Table3[[#This Row],[Location]],Table1[Location Name],Table1[FOB Risk Profile]) -> High | BM4: 46128
A5: 5985 | B5: Rick/Kathy Thorley | C5: rick@mcdok.com | D5: kathy@mcdok.com | E5: MCDOK | F5: Ashley Podroza | H5: =LEFT(Table1[[#This Row],[Supervisor]], SEARCH(" ", Table1[[#This Row],[Supervisor]]) - 1) & "@" & Table1[[#This Row],[Email Domain]] -> Ashley@mcdok.com | I5: Stacey Hyatt | J5: =LEFT(Table1[[#This Row],[GM]], SEARCH(" ", Table1[[#This Row],[GM]]) - 1) & "@" & Table1[[#This Row],[Email Domain]] -> Stacey@mcdok.com | K5: mcdok.com | L5: 490 | M5: ="mcdok.mdp+"&Table1[[#This Row],[Location Name]]&"@gmail.com" -> mcdok.mdp+5985@gmail.com | N5: ="Mcdok.mdp"&Table1[[#This Row],[Location Name]] -> Mcdok.mdp5985 | O5: 5985 - DURANT-US HWY 704/22 | P5: 2227 W Main St, Durant, OK, 74701, USA | Q5: Yes | R5: No | T5: Tuesday | U5: =_xlfn.XLOOKUP(Table1[[#This Row],[Location Name]],'Risk Profiles'!$A$18:$A$37,'Risk Profiles'!$B$18:$B$37) -> Low | V5: =_xlfn.XLOOKUP(Table1[[#This Row],[Location Name]],'Risk Profiles'!$A$18:$A$37,'Risk Profiles'!$C$18:$C$37) -> Within Normal range | W5: =_xlfn.XLOOKUP(Table1[[#This Row],[Location Name]],'Risk Profiles'!$A$18:$A$37,'Risk Profiles'!$D$18:$D$37) -> Low | X5: =_xlfn.XLOOKUP(Table1[[#This Row],[Location Name]],'Risk Profiles'!$A$18:$A$37,'Risk Profiles'!$E$18:$E$37) -> Within Normal range | Y5: Scauti/Chas | Z5: Yes | AA5: =_xlfn.XLOOKUP(A5,Table3[Location],Table3[Date Scheduled]) -> 46116 | AB5: Tuesday | AC5: Friday | AD5: Sunday | AE5: 46128 | AF5: Chasity | AG5: 46251 | AH5: Yes | AI5: Yes | AJ5: Yes | AK5: =IFERROR(INDEX('Scheduling Setup'!$L:$L,MATCH($A5,'Scheduling Setup'!$A:$A,0)),"") -> 46260 | BA5: 43380 | BB5: =_xlfn.XLOOKUP($BA5,$A$3:$A$32,$F$3:$F$32) -> Ashley Podroza | BC5: =_xlfn.XLOOKUP($BA5,$A$3:$A$32,$I$3:$I$32) -> Zukarr Eaves | BD5: =IF(_xlfn.XLOOKUP($BA5,$A$3:$A$32,$Y$3:$Y$32)="","",_xlfn.XLOOKUP($BA5,$A$3:$A$32,$Y$3:$Y$32)) -> Zukaar | BF5: 46088 | BH5: =_xlfn.XLOOKUP(Table3[[#This Row],[Location]],Table4[STORE '#],Table4[DATE RGR]) -> 46225 | BI5: =_xlfn.XLOOKUP(Table3[[#This Row],[Location]],Table1[Location Name],Table1[Weekly Inventory Count Day]) -> Saturday | BJ5: =_xlfn.XLOOKUP(Table3[[#This Row],[Location]],Table1[Location Name],Table1[FOB Risk Profile]) -> Medium | BM5: 46128
A6: 6972 | B6: Ryan Thorley | C6: =LEFT(Table1[[#This Row],[Owner/Operator]], SEARCH(" ", Table1[[#This Row],[Owner/Operator]]) - 1) & "@" & Table1[[#This Row],[Email Domain]] -> Ryan@mcdok.com | E6: MCDOK | F6: Robert Spencer | H6: =LEFT(Table1[[#This Row],[Supervisor]], SEARCH(" ", Table1[[#This Row],[Supervisor]]) - 1) & "@" & Table1[[#This Row],[Email Domain]] -> Robert@mcdok.com | I6: Nick Rice | J6: =LEFT(Table1[[#This Row],[GM]], SEARCH(" ", Table1[[#This Row],[GM]]) - 1) & "@" & Table1[[#This Row],[Email Domain]] -> Nick@mcdok.com | K6: mcdok.com | L6: 503 | M6: ="mcdok.mdp+"&Table1[[#This Row],[Location Name]]&"@gmail.com" -> mcdok.mdp+6972@gmail.com | N6: ="Mcdok.mdp"&Table1[[#This Row],[Location Name]] -> Mcdok.mdp6972 | O6: 6972 - ADA-COUNTRY CLUB | P6: 818 N Country Club Rd, Ada, OK, 74820, USA | Q6: Yes | R6: No | T6: Thursday | U6: =_xlfn.XLOOKUP(Table1[[#This Row],[Location Name]],'Risk Profiles'!$A$18:$A$37,'Risk Profiles'!$B$18:$B$37) -> Medium | V6: =_xlfn.XLOOKUP(Table1[[#This Row],[Location Name]],'Risk Profiles'!$A$18:$A$37,'Risk Profiles'!$C$18:$C$37) -> Within Normal Range | W6: =_xlfn.XLOOKUP(Table1[[#This Row],[Location Name]],'Risk Profiles'!$A$18:$A$37,'Risk Profiles'!$D$18:$D$37) -> Medium | X6: =_xlfn.XLOOKUP(Table1[[#This Row],[Location Name]],'Risk Profiles'!$A$18:$A$37,'Risk Profiles'!$E$18:$E$37) -> POS Overrings (0.38%)/Excessively High T-Reds | Y6: Beth | Z6: Yes | AA6: =_xlfn.XLOOKUP(A6,Table3[Location],Table3[Date Scheduled]) -> 46065 | AB6: Tuesday | AC6: Friday | AE6: 46128 | AF6: Bobbi | AG6: 46261 | AH6: Yes | AI6: Yes | AJ6: Yes | AK6: =IFERROR(INDEX('Scheduling Setup'!$L:$L,MATCH($A6,'Scheduling Setup'!$A:$A,0)),"") -> 46267 | BA6: 35064 | BB6: =_xlfn.XLOOKUP($BA6,$A$3:$A$32,$F$3:$F$32) -> Steven Vaughn | BC6: =_xlfn.XLOOKUP($BA6,$A$3:$A$32,$I$3:$I$32) -> Lynsey Yahola | BD6: =IF(_xlfn.XLOOKUP($BA6,$A$3:$A$32,$Y$3:$Y$32)="","",_xlfn.XLOOKUP($BA6,$A$3:$A$32,$Y$3:$Y$32)) -> Lynsey | BF6: 46092 | BH6: =_xlfn.XLOOKUP(Table3[[#This Row],[Location]],Table4[STORE '#],Table4[DATE RGR]) -> 46211 | BI6: =_xlfn.XLOOKUP(Table3[[#This Row],[Location]],Table1[Location Name],Table1[Weekly Inventory Count Day]) -> Wednesday | BJ6: =_xlfn.XLOOKUP(Table3[[#This Row],[Location]],Table1[Location Name],Table1[FOB Risk Profile]) -> High | BM6: 46128
A7: 10422 | B7: Rick/Kathy Thorley | C7: rick@mcdok.com | D7: kathy@mcdok.com | E7: MCDOK | F7: Ashley Podroza | H7: =LEFT(Table1[[#This Row],[Supervisor]], SEARCH(" ", Table1[[#This Row],[Supervisor]]) - 1) & "@" & Table1[[#This Row],[Email Domain]] -> Ashley@mcdok.com | I7: Ashleyh Hegwer | J7: =LEFT(Table1[[#This Row],[GM]], SEARCH(" ", Table1[[#This Row],[GM]]) - 1) & "@" & Table1[[#This Row],[Email Domain]] -> Ashleyh@mcdok.com | K7: mcdok.com | L7: 471 | M7: ="mcdok.mdp+"&Table1[[#This Row],[Location Name]]&"@gmail.com" -> mcdok.mdp+10422@gmail.com | N7: ="Mcdok.mdp"&Table1[[#This Row],[Location Name]] -> Mcdok.mdp10422 | O7: 10422 - ATOKA, OK-MISSISSIPPI | P7: 1100 S Mississippi Ave, Atoka, OK, 74525, USA | Q7: Yes | R7: No | T7: Saturday | U7: =_xlfn.XLOOKUP(Table1[[#This Row],[Location Name]],'Risk Profiles'!$A$18:$A$37,'Risk Profiles'!$B$18:$B$37) -> High | V7: =_xlfn.XLOOKUP(Table1[[#This Row],[Location Name]],'Risk Profiles'!$A$18:$A$37,'Risk Profiles'!$C$18:$C$37) -> High Stat Var (2.16%)/Coordinated Register Theft | W7: =_xlfn.XLOOKUP(Table1[[#This Row],[Location Name]],'Risk Profiles'!$A$18:$A$37,'Risk Profiles'!$D$18:$D$37) -> High | X7: =_xlfn.XLOOKUP(Table1[[#This Row],[Location Name]],'Risk Profiles'!$A$18:$A$37,'Risk Profiles'!$E$18:$E$37) -> POS Overrings (0.47%) | Y7: Ashley | Z7: Yes | AA7: =_xlfn.XLOOKUP(A7,Table3[Location],Table3[Date Scheduled]) -> 46095 | AB7: Wednesday | AC7: Sunday | AE7: 46128 | AF7: Peggy May | AG7: 46240 | AH7: Yes | AI7: Yes | AJ7: Yes | AK7: =IFERROR(INDEX('Scheduling Setup'!$L:$L,MATCH($A7,'Scheduling Setup'!$A:$A,0)),"") -> 46246 | BA7: 10422 | BB7: =_xlfn.XLOOKUP($BA7,$A$3:$A$32,$F$3:$F$32) -> Ashley Podroza | BC7: =_xlfn.XLOOKUP($BA7,$A$3:$A$32,$I$3:$I$32) -> Ashleyh Hegwer | BD7: =IF(_xlfn.XLOOKUP($BA7,$A$3:$A$32,$Y$3:$Y$32)="","",_xlfn.XLOOKUP($BA7,$A$3:$A$32,$Y$3:$Y$32)) -> Ashley | BF7: 46095 | BH7: =_xlfn.XLOOKUP(Table3[[#This Row],[Location]],Table4[STORE '#],Table4[DATE RGR]) -> 46051 | BI7: =_xlfn.XLOOKUP(Table3[[#This Row],[Location]],Table1[Location Name],Table1[Weekly Inventory Count Day]) -> Saturday | BJ7: =_xlfn.XLOOKUP(Table3[[#This Row],[Location]],Table1[Location Name],Table1[FOB Risk Profile]) -> High | BM7: 46128
A8: 10915 | B8: Ryan Thorley | C8: =LEFT(Table1[[#This Row],[Owner/Operator]], SEARCH(" ", Table1[[#This Row],[Owner/Operator]]) - 1) & "@" & Table1[[#This Row],[Email Domain]] -> Ryan@mcdok.com | E8: MCDOK | F8: Steven Vaughn | H8: =LEFT(Table1[[#This Row],[Supervisor]], SEARCH(" ", Table1[[#This Row],[Supervisor]]) - 1) & "@" & Table1[[#This Row],[Email Domain]] -> Steven@mcdok.com | I8: Caleb Nunnelley | J8: =LEFT(Table1[[#This Row],[GM]], SEARCH(" ", Table1[[#This Row],[GM]]) - 1) & "@" & Table1[[#This Row],[Email Domain]] -> Caleb@mcdok.com | K8: mcdok.com | L8: 458 | M8: ="mcdok.mdp+"&Table1[[#This Row],[Location Name]]&"@gmail.com" -> mcdok.mdp+10915@gmail.com | N8: ="Mcdok.mdp"&Table1[[#This Row],[Location Name]] -> Mcdok.mdp10915 | O8: 10915 - SEMINOLE, OK-MILT PHILLIPS | P8: 1423 Milt Phillips, Seminole, OK, 74868, USA | Q8: Yes | R8: No | T8: Wednesday | U8: =_xlfn.XLOOKUP(Table1[[#This Row],[Location Name]],'Risk Profiles'!$A$18:$A$37,'Risk Profiles'!$B$18:$B$37) -> Medium | V8: =_xlfn.XLOOKUP(Table1[[#This Row],[Location Name]],'Risk Profiles'!$A$18:$A$37,'Risk Profiles'!$C$18:$C$37) -> High Waste (1.06%) | W8: =_xlfn.XLOOKUP(Table1[[#This Row],[Location Name]],'Risk Profiles'!$A$18:$A$37,'Risk Profiles'!$D$18:$D$37) -> High | X8: =_xlfn.XLOOKUP(Table1[[#This Row],[Location Name]],'Risk Profiles'!$A$18:$A$37,'Risk Profiles'!$E$18:$E$37) -> T-Red After (0.45%), Discounts (6.55%) | Y8: Caitlin | Z8: Yes | AA8: =_xlfn.XLOOKUP(A8,Table3[Location],Table3[Date Scheduled]) -> 46148 | AB8: Thursday | AC8: Monday | AE8: 46129 | AF8: Tasha | AG8: 46252 | AH8: Yes | AI8: Yes | AJ8: Yes | AK8: =IFERROR(INDEX('Scheduling Setup'!$L:$L,MATCH($A8,'Scheduling Setup'!$A:$A,0)),"") -> 46260 | BA8: 29760 | BB8: =_xlfn.XLOOKUP($BA8,$A$3:$A$32,$F$3:$F$32) -> Krystiana Langford | BC8: =_xlfn.XLOOKUP($BA8,$A$3:$A$32,$I$3:$I$32) -> Heather Danforth | BD8: =IF(_xlfn.XLOOKUP($BA8,$A$3:$A$32,$Y$3:$Y$32)="","",_xlfn.XLOOKUP($BA8,$A$3:$A$32,$Y$3:$Y$32)) -> Magi | BF8: 46100 | BH8: =_xlfn.XLOOKUP(Table3[[#This Row],[Location]],Table4[STORE '#],Table4[DATE RGR]) -> 46323 | BI8: =_xlfn.XLOOKUP(Table3[[#This Row],[Location]],Table1[Location Name],Table1[Weekly Inventory Count Day]) -> Thursday | BJ8: =_xlfn.XLOOKUP(Table3[[#This Row],[Location]],Table1[Location Name],Table1[FOB Risk Profile]) -> Low | BM8: 46129
A9: 11657 | B9: Gary Mornhinweg | C9: =LEFT(Table1[[#This Row],[Owner/Operator]], SEARCH(" ", Table1[[#This Row],[Owner/Operator]]) - 1) & "@" & Table1[[#This Row],[Email Domain]] -> Gary@mcdok.com | E9: MCDOK | F9: Amanda Estrada | H9: =LEFT(Table1[[#This Row],[Supervisor]], SEARCH(" ", Table1[[#This Row],[Supervisor]]) - 1) & "@" & Table1[[#This Row],[Email Domain]] -> Amanda@mcdok.com | I9: Jessie Hiatt | J9: =LEFT(Table1[[#This Row],[GM]], SEARCH(" ", Table1[[#This Row],[GM]]) - 1) & "@" & Table1[[#This Row],[Email Domain]] -> Jessie@mcdok.com | K9: mcdok.com | L9: 440 | M9: ="mcdok.mdp+"&Table1[[#This Row],[Location Name]]&"@gmail.com" -> mcdok.mdp+11657@gmail.com | N9: ="Mcdok.mdp"&Table1[[#This Row],[Location Name]] -> Mcdok.mdp11657 | O9: 11657 - PURCELL | P9: 2211 S 9th Ave, Purcell, OK, 73080, USA | Q9: Yes | R9: No | T9: Thursday | U9: =_xlfn.XLOOKUP(Table1[[#This Row],[Location Name]],'Risk Profiles'!$A$18:$A$37,'Risk Profiles'!$B$18:$B$37) -> Medium | V9: =_xlfn.XLOOKUP(Table1[[#This Row],[Location Name]],'Risk Profiles'!$A$18:$A$37,'Risk Profiles'!$C$18:$C$37) -> High Waste (1.29%) | W9: =_xlfn.XLOOKUP(Table1[[#This Row],[Location Name]],'Risk Profiles'!$A$18:$A$37,'Risk Profiles'!$D$18:$D$37) -> Medium | X9: =_xlfn.XLOOKUP(Table1[[#This Row],[Location Name]],'Risk Profiles'!$A$18:$A$37,'Risk Profiles'!$E$18:$E$37) -> Within Normal range | Y9: Norma | Z9: Yes | AA9: =_xlfn.XLOOKUP(A9,Table3[Location],Table3[Date Scheduled]) -> 46149 | AB9: Tuesday | AC9: Friday | AE9: 46129 | AF9: Olivia | AG9: 46260 | AH9: Yes | AI9: Yes | AJ9: Yes | AK9: =IFERROR(INDEX('Scheduling Setup'!$L:$L,MATCH($A9,'Scheduling Setup'!$A:$A,0)),"") -> 46267 | BA9: 5985 | BB9: =_xlfn.XLOOKUP($BA9,$A$3:$A$32,$F$3:$F$32) -> Ashley Podroza | BC9: =_xlfn.XLOOKUP($BA9,$A$3:$A$32,$I$3:$I$32) -> Stacey Hyatt | BD9: =IF(_xlfn.XLOOKUP($BA9,$A$3:$A$32,$Y$3:$Y$32)="","",_xlfn.XLOOKUP($BA9,$A$3:$A$32,$Y$3:$Y$32)) -> Scauti/Chas | BE9: 4-6 Hours | BF9: 46116 | BG9: 0.33333333 | BH9: =_xlfn.XLOOKUP(Table3[[#This Row],[Location]],Table4[STORE '#],Table4[DATE RGR]) -> 46092 | BI9: =_xlfn.XLOOKUP(Table3[[#This Row],[Location]],Table1[Location Name],Table1[Weekly Inventory Count Day]) -> Tuesday | BJ9: =_xlfn.XLOOKUP(Table3[[#This Row],[Location]],Table1[Location Name],Table1[FOB Risk Profile]) -> Low | BK9: Earliest available date | BL9: Unchanged | BM9: 46129
A10: 13113 | B10: Rick/Kathy Thorley | C10: rick@mcdok.com | D10: kathy@mcdok.com | E10: MCDOK | F10: Ashley Podroza | H10: =LEFT(Table1[[#This Row],[Supervisor]], SEARCH(" ", Table1[[#This Row],[Supervisor]]) - 1) & "@" & Table1[[#This Row],[Email Domain]] -> Ashley@mcdok.com | I10: Chris Abbey | J10: =LEFT(Table1[[#This Row],[GM]], SEARCH(" ", Table1[[#This Row],[GM]]) - 1) & "@" & Table1[[#This Row],[Email Domain]] -> Chris@mcdok.com | K10: mcdok.com | L10: 454 | M10: ="mcdok.mdp+"&Table1[[#This Row],[Location Name]]&"@gmail.com" -> mcdok.mdp+13113@gmail.com | N10: ="Mcdok.mdp"&Table1[[#This Row],[Location Name]] -> Mcdok.mdp13113 | O10: 13113 - MADILL, HWY. 70 | P10: 511 S 1st St, Madill, OK, 73446, USA | Q10: Yes | R10: No | T10: Tuesday | U10: =_xlfn.XLOOKUP(Table1[[#This Row],[Location Name]],'Risk Profiles'!$A$18:$A$37,'Risk Profiles'!$B$18:$B$37) -> High | V10: =_xlfn.XLOOKUP(Table1[[#This Row],[Location Name]],'Risk Profiles'!$A$18:$A$37,'Risk Profiles'!$C$18:$C$37) -> High FOB% (5.58%), High Stat Var (2.40%) | W10: =_xlfn.XLOOKUP(Table1[[#This Row],[Location Name]],'Risk Profiles'!$A$18:$A$37,'Risk Profiles'!$D$18:$D$37) -> Medium | X10: =_xlfn.XLOOKUP(Table1[[#This Row],[Location Name]],'Risk Profiles'!$A$18:$A$37,'Risk Profiles'!$E$18:$E$37) -> POS Overrings (0.47%) | Y10: Josh | Z10: Yes | AA10: =_xlfn.XLOOKUP(A10,Table3[Location],Table3[Date Scheduled]) -> 46126 | AB10: Wednesday | AC10: Sunday | AE10: 46129 | AF10: Colton Standeraur | AG10: 46260 | AH10: Yes | AI10: Yes | AJ10: Yes | AK10: =IFERROR(INDEX('Scheduling Setup'!$L:$L,MATCH($A10,'Scheduling Setup'!$A:$A,0)),"") -> 46274 | BA10: 32525 | BB10: =_xlfn.XLOOKUP($BA10,$A$3:$A$32,$F$3:$F$32) -> Robert Spencer | BC10: =_xlfn.XLOOKUP($BA10,$A$3:$A$32,$I$3:$I$32) -> Aliyah Richardson | BD10: =IF(_xlfn.XLOOKUP($BA10,$A$3:$A$32,$Y$3:$Y$32)="","",_xlfn.XLOOKUP($BA10,$A$3:$A$32,$Y$3:$Y$32)) -> Priscilla | BE10: 4-6 Hours | BF10: 46121 | BG10: 0.33333333 | BH10: =_xlfn.XLOOKUP(Table3[[#This Row],[Location]],Table4[STORE '#],Table4[DATE RGR]) -> 46337 | BI10: =_xlfn.XLOOKUP(Table3[[#This Row],[Location]],Table1[Location Name],Table1[Weekly Inventory Count Day]) -> Thursday | BJ10: =_xlfn.XLOOKUP(Table3[[#This Row],[Location]],Table1[Location Name],Table1[FOB Risk Profile]) -> High | BK10: Earliest available date | BL10: Unchanged | BM10: 46129
A11: 18213 | B11: Gary Mornhinweg | C11: =LEFT(Table1[[#This Row],[Owner/Operator]], SEARCH(" ", Table1[[#This Row],[Owner/Operator]]) - 1) & "@" & Table1[[#This Row],[Email Domain]] -> Gary@mcdok.com | E11: MCDOK | F11: Krystiana Langford | H11: =LEFT(Table1[[#This Row],[Supervisor]], SEARCH(" ", Table1[[#This Row],[Supervisor]]) - 1) & "@" & Table1[[#This Row],[Email Domain]] -> Krystiana@mcdok.com | I11: Cora Bahling | J11: =LEFT(Table1[[#This Row],[GM]], SEARCH(" ", Table1[[#This Row],[GM]]) - 1) & "@" & Table1[[#This Row],[Email Domain]] -> Cora@mcdok.com | K11: mcdok.com | L11: 435 | M11: ="mcdok.mdp+"&Table1[[#This Row],[Location Name]]&"@gmail.com" -> mcdok.mdp+18213@gmail.com | N11: ="Mcdok.mdp"&Table1[[#This Row],[Location Name]] -> Mcdok.mdp18213 | O11: 18213 - LINDSAY, OK-WAL*MART | P11: 407 Linwood Plz, Lindsay, OK, 73052, USA | Q11: Yes | R11: No | T11: Thursday | U11: =_xlfn.XLOOKUP(Table1[[#This Row],[Location Name]],'Risk Profiles'!$A$18:$A$37,'Risk Profiles'!$B$18:$B$37) -> Medium | V11: =_xlfn.XLOOKUP(Table1[[#This Row],[Location Name]],'Risk Profiles'!$A$18:$A$37,'Risk Profiles'!$C$18:$C$37) -> High Waste (1.16%) | W11: =_xlfn.XLOOKUP(Table1[[#This Row],[Location Name]],'Risk Profiles'!$A$18:$A$37,'Risk Profiles'!$D$18:$D$37) -> Medium | X11: =_xlfn.XLOOKUP(Table1[[#This Row],[Location Name]],'Risk Profiles'!$A$18:$A$37,'Risk Profiles'!$E$18:$E$37) -> Within Normal range | Y11: Crystal | Z11: Yes | AA11: =_xlfn.XLOOKUP(A11,Table3[Location],Table3[Date Scheduled]) -> 46177 | AB11: Tuesday | AC11: Friday | AE11: 46129 | AF11: Brad | AG11: 46247 | AH11: Yes | AI11: Yes | AJ11: Yes | AK11: =IFERROR(INDEX('Scheduling Setup'!$L:$L,MATCH($A11,'Scheduling Setup'!$A:$A,0)),"") -> 46253 | BA11: 20475 | BB11: =_xlfn.XLOOKUP($BA11,$A$3:$A$32,$F$3:$F$32) -> Amanda Estrada | BC11: =_xlfn.XLOOKUP($BA11,$A$3:$A$32,$I$3:$I$32) -> Derek McGirt | BD11: =IF(_xlfn.XLOOKUP($BA11,$A$3:$A$32,$Y$3:$Y$32)="","",_xlfn.XLOOKUP($BA11,$A$3:$A$32,$Y$3:$Y$32)) -> Susanna | BE11: 4-6 Hours | BF11: 46122 | BG11: 0.33333333 | BH11: =_xlfn.XLOOKUP(Table3[[#This Row],[Location]],Table4[STORE '#],Table4[DATE RGR]) -> 46107 | BI11: =_xlfn.XLOOKUP(Table3[[#This Row],[Location]],Table1[Location Name],Table1[Weekly Inventory Count Day]) -> Thursday | BJ11: =_xlfn.XLOOKUP(Table3[[#This Row],[Location]],Table1[Location Name],Table1[FOB Risk Profile]) -> Low | BK11: Earliest available date | BL11: Unchanged | BM11: 46129
A12: 20475 | B12: Gary Mornhinweg | C12: =LEFT(Table1[[#This Row],[Owner/Operator]], SEARCH(" ", Table1[[#This Row],[Owner/Operator]]) - 1) & "@" & Table1[[#This Row],[Email Domain]] -> Gary@mcdok.com | E12: MCDOK | F12: Amanda Estrada | H12: =LEFT(Table1[[#This Row],[Supervisor]], SEARCH(" ", Table1[[#This Row],[Supervisor]]) - 1) & "@" & Table1[[#This Row],[Email Domain]] -> Amanda@mcdok.com | I12: Derek McGirt | J12: =LEFT(Table1[[#This Row],[GM]], SEARCH(" ", Table1[[#This Row],[GM]]) - 1) & "@" & Table1[[#This Row],[Email Domain]] -> Derek@mcdok.com | K12: mcdok.com | L12: 451 | M12: ="mcdok.mdp+"&Table1[[#This Row],[Location Name]]&"@gmail.com" -> mcdok.mdp+20475@gmail.com | N12: ="Mcdok.mdp"&Table1[[#This Row],[Location Name]] -> Mcdok.mdp20475 | O12: 20475 - OKC-I-240/SOONER | P12: 7800 S Sooner Rd, Oklahoma City, OK, 73135, USA | Q12: Yes | R12: No | T12: Thursday | U12: =_xlfn.XLOOKUP(Table1[[#This Row],[Location Name]],'Risk Profiles'!$A$18:$A$37,'Risk Profiles'!$B$18:$B$37) -> Low | V12: =_xlfn.XLOOKUP(Table1[[#This Row],[Location Name]],'Risk Profiles'!$A$18:$A$37,'Risk Profiles'!$C$18:$C$37) -> Within Normal range | W12: =_xlfn.XLOOKUP(Table1[[#This Row],[Location Name]],'Risk Profiles'!$A$18:$A$37,'Risk Profiles'!$D$18:$D$37) -> Medium | X12: =_xlfn.XLOOKUP(Table1[[#This Row],[Location Name]],'Risk Profiles'!$A$18:$A$37,'Risk Profiles'!$E$18:$E$37) -> T-Red After (0.38%), Discounts (7.40%) | Y12: Susanna | Z12: Yes | AA12: =_xlfn.XLOOKUP(A12,Table3[Location],Table3[Date Scheduled]) -> 46122 | AB12: Tuesday | AC12: Friday | AE12: 46129 | AF12: Rebecca | AG12: 46239 | AH12: Yes | AI12: Yes | AJ12: Yes | AK12: =IFERROR(INDEX('Scheduling Setup'!$L:$L,MATCH($A12,'Scheduling Setup'!$A:$A,0)),"") -> 46246 | BA12: 13113 | BB12: =_xlfn.XLOOKUP($BA12,$A$3:$A$32,$F$3:$F$32) -> Ashley Podroza | BC12: =_xlfn.XLOOKUP($BA12,$A$3:$A$32,$I$3:$I$32) -> Chris Abbey | BD12: =IF(_xlfn.XLOOKUP($BA12,$A$3:$A$32,$Y$3:$Y$32)="","",_xlfn.XLOOKUP($BA12,$A$3:$A$32,$Y$3:$Y$32)) -> Josh | BE12: 4-6 Hours | BF12: 46126 | BG12: 0.33333333 | BH12: =_xlfn.XLOOKUP(Table3[[#This Row],[Location]],Table4[STORE '#],Table4[DATE RGR]) -> 46183 | BI12: =_xlfn.XLOOKUP(Table3[[#This Row],[Location]],Table1[Location Name],Table1[Weekly Inventory Count Day]) -> Tuesday | BJ12: =_xlfn.XLOOKUP(Table3[[#This Row],[Location]],Table1[Location Name],Table1[FOB Risk Profile]) -> High | BK12: Earliest available date | BL12: Unchanged | BM12: 46129
A13: 24471 | B13: Ryan Thorley | C13: =LEFT(Table1[[#This Row],[Owner/Operator]], SEARCH(" ", Table1[[#This Row],[Owner/Operator]]) - 1) & "@" & Table1[[#This Row],[Email Domain]] -> Ryan@mcdok.com | E13: MCDOK | F13: Robert Spencer | H13: =LEFT(Table1[[#This Row],[Supervisor]], SEARCH(" ", Table1[[#This Row],[Supervisor]]) - 1) & "@" & Table1[[#This Row],[Email Domain]] -> Robert@mcdok.com | I13: Mystykal Abbey | J13: =LEFT(Table1[[#This Row],[GM]], SEARCH(" ", Table1[[#This Row],[GM]]) - 1) & "@" & Table1[[#This Row],[Email Domain]] -> Mystykal@mcdok.com | K13: mcdok.com | L13: 459 | M13: ="mcdok.mdp+"&Table1[[#This Row],[Location Name]]&"@gmail.com" -> mcdok.mdp+24471@gmail.com | N13: ="Mcdok.mdp"&Table1[[#This Row],[Location Name]] -> Mcdok.mdp24471 | O13: 24471 - ARDMORE, OK-NEC COOPER/12TH | P13: 1202 Cooper Dr, Ardmore, OK, 73401, USA | Q13: Yes | R13: No | T13: Thursday | U13: =_xlfn.XLOOKUP(Table1[[#This Row],[Location Name]],'Risk Profiles'!$A$18:$A$37,'Risk Profiles'!$B$18:$B$37) -> High | V13: =_xlfn.XLOOKUP(Table1[[#This Row],[Location Name]],'Risk Profiles'!$A$18:$A$37,'Risk Profiles'!$C$18:$C$37) -> High FOB% (5.55%), High Stat Var (2.04%) | W13: =_xlfn.XLOOKUP(Table1[[#This Row],[Location Name]],'Risk Profiles'!$A$18:$A$37,'Risk Profiles'!$D$18:$D$37) -> Medium | X13: =_xlfn.XLOOKUP(Table1[[#This Row],[Location Name]],'Risk Profiles'!$A$18:$A$37,'Risk Profiles'!$E$18:$E$37) -> Within Normal range | Y13: Mystikal | Z13: Yes | AA13: =_xlfn.XLOOKUP(A13,Table3[Location],Table3[Date Scheduled]) -> 46086 | AB13: Wednesday | AC13: Sunday | AE13: 46129 | AF13: Rasheda | AG13: 46268 | AH13: Yes | AI13: Yes | AJ13: Yes | AK13: =IFERROR(INDEX('Scheduling Setup'!$L:$L,MATCH($A13,'Scheduling Setup'!$A:$A,0)),"") -> 46274 | BA13: 3708 | BB13: =_xlfn.XLOOKUP($BA13,$A$3:$A$32,$F$3:$F$32) -> Robert Spencer | BC13: =_xlfn.XLOOKUP($BA13,$A$3:$A$32,$I$3:$I$32) -> Cinthya Armedariz | BD13: =IF(_xlfn.XLOOKUP($BA13,$A$3:$A$32,$Y$3:$Y$32)="","",_xlfn.XLOOKUP($BA13,$A$3:$A$32,$Y$3:$Y$32)) -> Cinthya | BE13: 4-6 Hours | BF13: 46133 | BG13: 0.33333333 | BH13: =_xlfn.XLOOKUP(Table3[[#This Row],[Location]],Table4[STORE '#],Table4[DATE RGR]) -> 46260 | BI13: =_xlfn.XLOOKUP(Table3[[#This Row],[Location]],Table1[Location Name],Table1[Weekly Inventory Count Day]) -> Tuesday | BJ13: =_xlfn.XLOOKUP(Table3[[#This Row],[Location]],Table1[Location Name],Table1[FOB Risk Profile]) -> Medium | BK13: Earliest available date | BL13: Unchanged | BM13: 46129
A14: 29760 | B14: Ryan Thorley | C14: =LEFT(Table1[[#This Row],[Owner/Operator]], SEARCH(" ", Table1[[#This Row],[Owner/Operator]]) - 1) & "@" & Table1[[#This Row],[Email Domain]] -> Ryan@mcdok.com | E14: MCDOK | F14: Krystiana Langford | H14: =LEFT(Table1[[#This Row],[Supervisor]], SEARCH(" ", Table1[[#This Row],[Supervisor]]) - 1) & "@" & Table1[[#This Row],[Email Domain]] -> Krystiana@mcdok.com | I14: Heather Danforth | J14: =LEFT(Table1[[#This Row],[GM]], SEARCH(" ", Table1[[#This Row],[GM]]) - 1) & "@" & Table1[[#This Row],[Email Domain]] -> Heather@mcdok.com | K14: mcdok.com | L14: 483 | M14: ="mcdok.mdp+"&Table1[[#This Row],[Location Name]]&"@gmail.com" -> mcdok.mdp+29760@gmail.com | N14: ="Mcdok.mdp"&Table1[[#This Row],[Location Name]] -> Mcdok.mdp29760 | O14: 29760 - DUNCAN, OK-HWY 81 (RELO) | P14: 1817 N Highway 81, Duncan, OK, 73533, USA | Q14: Yes | R14: No | T14: Thursday | U14: =_xlfn.XLOOKUP(Table1[[#This Row],[Location Name]],'Risk Profiles'!$A$18:$A$37,'Risk Profiles'!$B$18:$B$37) -> Low | V14: =_xlfn.XLOOKUP(Table1[[#This Row],[Location Name]],'Risk Profiles'!$A$18:$A$37,'Risk Profiles'!$C$18:$C$37) -> Within Normal range | W14: =_xlfn.XLOOKUP(Table1[[#This Row],[Location Name]],'Risk Profiles'!$A$18:$A$37,'Risk Profiles'!$D$18:$D$37) -> Low | X14: =_xlfn.XLOOKUP(Table1[[#This Row],[Location Name]],'Risk Profiles'!$A$18:$A$37,'Risk Profiles'!$E$18:$E$37) -> Within Normal range | Y14: Magi | Z14: Yes | AA14: =_xlfn.XLOOKUP(A14,Table3[Location],Table3[Date Scheduled]) -> 46100 | AB14: Tuesday | AC14: Friday | AE14: 46129 | AF14: Stephanie | AG14: 46267 | AH14: Yes | AI14: Yes | AJ14: Yes | AK14: =IFERROR(INDEX('Scheduling Setup'!$L:$L,MATCH($A14,'Scheduling Setup'!$A:$A,0)),"") -> 46267 | BA14: 33222 | BB14: =_xlfn.XLOOKUP($BA14,$A$3:$A$32,$F$3:$F$32) -> Krystiana Langford | BC14: =_xlfn.XLOOKUP($BA14,$A$3:$A$32,$I$3:$I$32) -> Carol Escusa | BD14: =IF(_xlfn.XLOOKUP($BA14,$A$3:$A$32,$Y$3:$Y$32)="","",_xlfn.XLOOKUP($BA14,$A$3:$A$32,$Y$3:$Y$32)) -> Darryl | BE14: 4-6 Hours | BF14: 46135 | BG14: 0.33333333 | BH14: =_xlfn.XLOOKUP(Table3[[#This Row],[Location]],Table4[STORE '#],Table4[DATE RGR]) -> 46169 | BI14: =_xlfn.XLOOKUP(Table3[[#This Row],[Location]],Table1[Location Name],Table1[Weekly Inventory Count Day]) -> Thursday | BJ14: =_xlfn.XLOOKUP(Table3[[#This Row],[Location]],Table1[Location Name],Table1[FOB Risk Profile]) -> High | BK14: Earliest available date | BL14: Changed Fdrom 04/02/26 | BM14: 46129
A15: 31357 | B15: Ryan Thorley | C15: =LEFT(Table1[[#This Row],[Owner/Operator]], SEARCH(" ", Table1[[#This Row],[Owner/Operator]]) - 1) & "@" & Table1[[#This Row],[Email Domain]] -> Ryan@mcdok.com | E15: MCDOK | F15: Amanda Estrada | H15: =LEFT(Table1[[#This Row],[Supervisor]], SEARCH(" ", Table1[[#This Row],[Supervisor]]) - 1) & "@" & Table1[[#This Row],[Email Domain]] -> Amanda@mcdok.com | I15: Brady Giambaresi | J15: =LEFT(Table1[[#This Row],[GM]], SEARCH(" ", Table1[[#This Row],[GM]]) - 1) & "@" & Table1[[#This Row],[Email Domain]] -> Brady@mcdok.com | K15: mcdok.com | L15: 443 | M15: ="mcdok.mdp+"&Table1[[#This Row],[Location Name]]&"@gmail.com" -> mcdok.mdp+31357@gmail.com | N15: ="Mcdok.mdp"&Table1[[#This Row],[Location Name]] -> Mcdok.mdp31357 | O15: 31357 - PAULS VALLEY RELO - BALLARD RD NO. | P15: 2635 W Grant Ave, Pauls Valley, OK, 73075, USA | Q15: Yes | R15: No | T15: Thursday | U15: =_xlfn.XLOOKUP(Table1[[#This Row],[Location Name]],'Risk Profiles'!$A$18:$A$37,'Risk Profiles'!$B$18:$B$37) -> Medium | V15: =_xlfn.XLOOKUP(Table1[[#This Row],[Location Name]],'Risk Profiles'!$A$18:$A$37,'Risk Profiles'!$C$18:$C$37) -> Within Normal range | W15: =_xlfn.XLOOKUP(Table1[[#This Row],[Location Name]],'Risk Profiles'!$A$18:$A$37,'Risk Profiles'!$D$18:$D$37) -> Medium | X15: =_xlfn.XLOOKUP(Table1[[#This Row],[Location Name]],'Risk Profiles'!$A$18:$A$37,'Risk Profiles'!$E$18:$E$37) -> Within Normal range | Y15: Angelo | Z15: Yes | AA15: =_xlfn.XLOOKUP(A15,Table3[Location],Table3[Date Scheduled]) -> 46156 | AB15: Tuesday | AC15: Friday | AE15: 46129 | AF15: Ashleigh | AG15: 46261 | AH15: Yes | AI15: Yes | AJ15: Yes | AK15: =IFERROR(INDEX('Scheduling Setup'!$L:$L,MATCH($A15,'Scheduling Setup'!$A:$A,0)),"") -> 46267 | BA15: 10915 | BB15: =_xlfn.XLOOKUP($BA15,$A$3:$A$32,$F$3:$F$32) -> Steven Vaughn | BC15: =_xlfn.XLOOKUP($BA15,$A$3:$A$32,$I$3:$I$32) -> Caleb Nunnelley | BD15: =IF(_xlfn.XLOOKUP($BA15,$A$3:$A$32,$Y$3:$Y$32)="","",_xlfn.XLOOKUP($BA15,$A$3:$A$32,$Y$3:$Y$32)) -> Caitlin | BE15: 4-6 Hours | BF15: 46148 | BG15: 0.33333333 | BH15: =_xlfn.XLOOKUP(Table3[[#This Row],[Location]],Table4[STORE '#],Table4[DATE RGR]) -> 46071 | BI15: =_xlfn.XLOOKUP(Table3[[#This Row],[Location]],Table1[Location Name],Table1[Weekly Inventory Count Day]) -> Wednesday | BJ15: =_xlfn.XLOOKUP(Table3[[#This Row],[Location]],Table1[Location Name],Table1[FOB Risk Profile]) -> Medium | BK15: Earliest available date | BL15: Unchanged | BM15: 46129
A16: 32525 | B16: Ryan Thorley | C16: =LEFT(Table1[[#This Row],[Owner/Operator]], SEARCH(" ", Table1[[#This Row],[Owner/Operator]]) - 1) & "@" & Table1[[#This Row],[Email Domain]] -> Ryan@mcdok.com | E16: MCDOK | F16: Robert Spencer | H16: =LEFT(Table1[[#This Row],[Supervisor]], SEARCH(" ", Table1[[#This Row],[Supervisor]]) - 1) & "@" & Table1[[#This Row],[Email Domain]] -> Robert@mcdok.com | I16: Aliyah Richardson | J16: =LEFT(Table1[[#This Row],[GM]], SEARCH(" ", Table1[[#This Row],[GM]]) - 1) & "@" & Table1[[#This Row],[Email Domain]] -> Aliyah@mcdok.com | K16: mcdok.com | L16: 440 | M16: ="mcdok.mdp+"&Table1[[#This Row],[Location Name]]&"@gmail.com" -> mcdok.mdp+32525@gmail.com | N16: ="Mcdok.mdp"&Table1[[#This Row],[Location Name]] -> Mcdok.mdp32525 | O16: 32525 - SULPHUR, OK | P16: 2539 W Broadway Ave, Sulphur, OK, 73086, USA | Q16: Yes | R16: No | T16: Thursday | U16: =_xlfn.XLOOKUP(Table1[[#This Row],[Location Name]],'Risk Profiles'!$A$18:$A$37,'Risk Profiles'!$B$18:$B$37) -> High | V16: =_xlfn.XLOOKUP(Table1[[#This Row],[Location Name]],'Risk Profiles'!$A$18:$A$37,'Risk Profiles'!$C$18:$C$37) -> High FOB% (5.27%), High Waste (1.51%) | W16: =_xlfn.XLOOKUP(Table1[[#This Row],[Location Name]],'Risk Profiles'!$A$18:$A$37,'Risk Profiles'!$D$18:$D$37) -> Low | X16: =_xlfn.XLOOKUP(Table1[[#This Row],[Location Name]],'Risk Profiles'!$A$18:$A$37,'Risk Profiles'!$E$18:$E$37) -> Within Normal range | Y16: Priscilla | Z16: Yes | AA16: =_xlfn.XLOOKUP(A16,Table3[Location],Table3[Date Scheduled]) -> 46121 | AB16: Tuesday | AC16: Friday | AE16: 46129 | AF16: Sarah | AG16: 46251 | AH16: Yes | AI16: Yes | AJ16: Yes | AK16: =IFERROR(INDEX('Scheduling Setup'!$L:$L,MATCH($A16,'Scheduling Setup'!$A:$A,0)),"") -> 46267 | BA16: 11657 | BB16: =_xlfn.XLOOKUP($BA16,$A$3:$A$32,$F$3:$F$32) -> Amanda Estrada | BC16: =_xlfn.XLOOKUP($BA16,$A$3:$A$32,$I$3:$I$32) -> Jessie Hiatt | BD16: =IF(_xlfn.XLOOKUP($BA16,$A$3:$A$32,$Y$3:$Y$32)="","",_xlfn.XLOOKUP($BA16,$A$3:$A$32,$Y$3:$Y$32)) -> Norma | BE16: 4-6 Hours | BF16: 46149 | BG16: 0.33333333 | BH16: =_xlfn.XLOOKUP(Table3[[#This Row],[Location]],Table4[STORE '#],Table4[DATE RGR]) -> 46134 | BI16: =_xlfn.XLOOKUP(Table3[[#This Row],[Location]],Table1[Location Name],Table1[Weekly Inventory Count Day]) -> Thursday | BJ16: =_xlfn.XLOOKUP(Table3[[#This Row],[Location]],Table1[Location Name],Table1[FOB Risk Profile]) -> Medium | BK16: Earliest available date | BL16: Changed from 06/04/26 | BM16: 46129
A17: 33109 | B17: Rick/Kathy Thorley | C17: rick@mcdok.com | D17: kathy@mcdok.com | E17: MCDOK | F17: Ashley Podroza | H17: =LEFT(Table1[[#This Row],[Supervisor]], SEARCH(" ", Table1[[#This Row],[Supervisor]]) - 1) & "@" & Table1[[#This Row],[Email Domain]] -> Ashley@mcdok.com | I17: Rey Araiz | J17: =LEFT(Table1[[#This Row],[GM]], SEARCH(" ", Table1[[#This Row],[GM]]) - 1) & "@" & Table1[[#This Row],[Email Domain]] -> Rey@mcdok.com | K17: mcdok.com | L17: 427 | M17: ="mcdok.mdp+"&Table1[[#This Row],[Location Name]]&"@gmail.com" -> mcdok.mdp+33109@gmail.com | N17: ="Mcdok.mdp"&Table1[[#This Row],[Location Name]] -> Mcdok.mdp33109 | O17: 33109 - MARIETTA, OK | P17: 1303 Memorial Dr, Marietta, OK, 73448, USA | Q17: Yes | R17: No | T17: Tuesday | U17: =_xlfn.XLOOKUP(Table1[[#This Row],[Location Name]],'Risk Profiles'!$A$18:$A$37,'Risk Profiles'!$B$18:$B$37) -> Low | V17: =_xlfn.XLOOKUP(Table1[[#This Row],[Location Name]],'Risk Profiles'!$A$18:$A$37,'Risk Profiles'!$C$18:$C$37) -> Within Normal range | W17: =_xlfn.XLOOKUP(Table1[[#This Row],[Location Name]],'Risk Profiles'!$A$18:$A$37,'Risk Profiles'!$D$18:$D$37) -> Low | X17: =_xlfn.XLOOKUP(Table1[[#This Row],[Location Name]],'Risk Profiles'!$A$18:$A$37,'Risk Profiles'!$E$18:$E$37) -> Within Normal range | Y17: Gisselle | Z17: Yes | AA17: =_xlfn.XLOOKUP(A17,Table3[Location],Table3[Date Scheduled]) -> 46170 | AB17: Wednesday | AC17: Sunday | AE17: 46129 | AF17: Angie | AG17: 46252 | AH17: Yes | AI17: Yes | AJ17: Yes | AK17: =IFERROR(INDEX('Scheduling Setup'!$L:$L,MATCH($A17,'Scheduling Setup'!$A:$A,0)),"") -> 46260 | BA17: 31357 | BB17: =_xlfn.XLOOKUP($BA17,$A$3:$A$32,$F$3:$F$32) -> Amanda Estrada | BC17: =_xlfn.XLOOKUP($BA17,$A$3:$A$32,$I$3:$I$32) -> Brady Giambaresi | BD17: =IF(_xlfn.XLOOKUP($BA17,$A$3:$A$32,$Y$3:$Y$32)="","",_xlfn.XLOOKUP($BA17,$A$3:$A$32,$Y$3:$Y$32)) -> Angelo | BE17: 4-6 Hours | BF17: 46156 | BG17: 0.33333333 | BH17: =_xlfn.XLOOKUP(Table3[[#This Row],[Location]],Table4[STORE '#],Table4[DATE RGR]) -> 46197 | BI17: =_xlfn.XLOOKUP(Table3[[#This Row],[Location]],Table1[Location Name],Table1[Weekly Inventory Count Day]) -> Thursday | BJ17: =_xlfn.XLOOKUP(Table3[[#This Row],[Location]],Table1[Location Name],Table1[FOB Risk Profile]) -> Medium | BK17: Earliest available date | BL17: Unchanged | BM17: 46129
A18: 33222 | B18: Ryan Thorley | C18: =LEFT(Table1[[#This Row],[Owner/Operator]], SEARCH(" ", Table1[[#This Row],[Owner/Operator]]) - 1) & "@" & Table1[[#This Row],[Email Domain]] -> Ryan@mcdok.com | E18: MCDOK | F18: Krystiana Langford | H18: =LEFT(Table1[[#This Row],[Supervisor]], SEARCH(" ", Table1[[#This Row],[Supervisor]]) - 1) & "@" & Table1[[#This Row],[Email Domain]] -> Krystiana@mcdok.com | I18: Carol Escusa | J18: =LEFT(Table1[[#This Row],[GM]], SEARCH(" ", Table1[[#This Row],[GM]]) - 1) & "@" & Table1[[#This Row],[Email Domain]] -> Carol@mcdok.com | K18: mcdok.com | L18: 440 | M18: ="mcdok.mdp+"&Table1[[#This Row],[Location Name]]&"@gmail.com" -> mcdok.mdp+33222@gmail.com | N18: ="Mcdok.mdp"&Table1[[#This Row],[Location Name]] -> Mcdok.mdp33222 | O18: 33222 - ELGIN, OK - STO | P18: 7738 US Highway 277, Elgin, OK, 73538, USA | Q18: Yes | R18: Yes | S18: 46082 | T18: Thursday | U18: =_xlfn.XLOOKUP(Table1[[#This Row],[Location Name]],'Risk Profiles'!$A$18:$A$37,'Risk Profiles'!$B$18:$B$37) -> High | V18: =_xlfn.XLOOKUP(Table1[[#This Row],[Location Name]],'Risk Profiles'!$A$18:$A$37,'Risk Profiles'!$C$18:$C$37) -> Bulk Theft/Untracked Waste | W18: =_xlfn.XLOOKUP(Table1[[#This Row],[Location Name]],'Risk Profiles'!$A$18:$A$37,'Risk Profiles'!$D$18:$D$37) -> Low | X18: =_xlfn.XLOOKUP(Table1[[#This Row],[Location Name]],'Risk Profiles'!$A$18:$A$37,'Risk Profiles'!$E$18:$E$37) -> Within Normal range | Y18: Darryl | Z18: Yes | AA18: =_xlfn.XLOOKUP(A18,Table3[Location],Table3[Date Scheduled]) -> 46135 | AB18: Tuesday | AC18: Friday | AE18: 46129 | AF18: Stephanie | AG18: 46267 | AH18: Yes | AI18: Yes | AJ18: Yes | AK18: =IFERROR(INDEX('Scheduling Setup'!$L:$L,MATCH($A18,'Scheduling Setup'!$A:$A,0)),"") -> 46274 | BA18: 33704 | BB18: =_xlfn.XLOOKUP($BA18,$A$3:$A$32,$F$3:$F$32) -> Steven Vaughn | BC18: =_xlfn.XLOOKUP($BA18,$A$3:$A$32,$I$3:$I$32) -> Candy Barksdale | BD18: =IF(_xlfn.XLOOKUP($BA18,$A$3:$A$32,$Y$3:$Y$32)="","",_xlfn.XLOOKUP($BA18,$A$3:$A$32,$Y$3:$Y$32)) -> Marlena | BE18: 4-6 Hours | BF18: 46157 | BG18: 0.33333333 | BH18: =_xlfn.XLOOKUP(Table3[[#This Row],[Location]],Table4[STORE '#],Table4[DATE RGR]) -> 46127 | BI18: =_xlfn.XLOOKUP(Table3[[#This Row],[Location]],Table1[Location Name],Table1[Weekly Inventory Count Day]) -> Friday | BJ18: =_xlfn.XLOOKUP(Table3[[#This Row],[Location]],Table1[Location Name],Table1[FOB Risk Profile]) -> Medium | BK18: Earliest available date | BL18: Unchanged | BM18: 46129
A19: 33704 | B19: Gary Mornhinweg | C19: =LEFT(Table1[[#This Row],[Owner/Operator]], SEARCH(" ", Table1[[#This Row],[Owner/Operator]]) - 1) & "@" & Table1[[#This Row],[Email Domain]] -> Gary@mcdok.com | E19: MCDOK | F19: Steven Vaughn | H19: =LEFT(Table1[[#This Row],[Supervisor]], SEARCH(" ", Table1[[#This Row],[Supervisor]]) - 1) & "@" & Table1[[#This Row],[Email Domain]] -> Steven@mcdok.com | I19: Candy Barksdale | J19: =LEFT(Table1[[#This Row],[GM]], SEARCH(" ", Table1[[#This Row],[GM]]) - 1) & "@" & Table1[[#This Row],[Email Domain]] -> Candy@mcdok.com | K19: mcdok.com | L19: 448 | M19: ="mcdok.mdp+"&Table1[[#This Row],[Location Name]]&"@gmail.com" -> mcdok.mdp+33704@gmail.com | N19: ="Mcdok.mdp"&Table1[[#This Row],[Location Name]] -> Mcdok.mdp33704 | O19: 33704 - TECUMSEH, OK | P19: 1210 Gordon Cooper Dr, Tecumseh, OK, 74873, USA | Q19: Yes | R19: No | T19: Friday | U19: =_xlfn.XLOOKUP(Table1[[#This Row],[Location Name]],'Risk Profiles'!$A$18:$A$37,'Risk Profiles'!$B$18:$B$37) -> Medium | V19: =_xlfn.XLOOKUP(Table1[[#This Row],[Location Name]],'Risk Profiles'!$A$18:$A$37,'Risk Profiles'!$C$18:$C$37) -> Within Normal range | W19: =_xlfn.XLOOKUP(Table1[[#This Row],[Location Name]],'Risk Profiles'!$A$18:$A$37,'Risk Profiles'!$D$18:$D$37) -> Medium | X19: =_xlfn.XLOOKUP(Table1[[#This Row],[Location Name]],'Risk Profiles'!$A$18:$A$37,'Risk Profiles'!$E$18:$E$37) -> High Discounts (7.10%) | Y19: Marlena | Z19: Yes | AA19: =_xlfn.XLOOKUP(A19,Table3[Location],Table3[Date Scheduled]) -> 46157 | AB19: Monday | AC19: Thursday | AE19: 46129 | AF19: Bella | AG19: 46246 | AH19: Yes | AI19: Yes | AJ19: Yes | AK19: =IFERROR(INDEX('Scheduling Setup'!$L:$L,MATCH($A19,'Scheduling Setup'!$A:$A,0)),"") -> 46253 | BA19: 34222 | BB19: =_xlfn.XLOOKUP($BA19,$A$3:$A$32,$F$3:$F$32) -> Steven Vaughn | BC19: =_xlfn.XLOOKUP($BA19,$A$3:$A$32,$I$3:$I$32) -> Hunter McKee | BD19: =IF(_xlfn.XLOOKUP($BA19,$A$3:$A$32,$Y$3:$Y$32)="","",_xlfn.XLOOKUP($BA19,$A$3:$A$32,$Y$3:$Y$32)) -> Kaylee | BE19: 4-6 Hours | BF19: 46162 | BG19: 0.375 | BH19: =_xlfn.XLOOKUP(Table3[[#This Row],[Location]],Table4[STORE '#],Table4[DATE RGR]) -> 46155 | BI19: =_xlfn.XLOOKUP(Table3[[#This Row],[Location]],Table1[Location Name],Table1[Weekly Inventory Count Day]) -> Monday | BJ19: =_xlfn.XLOOKUP(Table3[[#This Row],[Location]],Table1[Location Name],Table1[FOB Risk Profile]) -> Low | BK19: Earliest available date | BL19: Unchanged | BM19: 46129
A20: 34222 | B20: Gary Mornhinweg | C20: =LEFT(Table1[[#This Row],[Owner/Operator]], SEARCH(" ", Table1[[#This Row],[Owner/Operator]]) - 1) & "@" & Table1[[#This Row],[Email Domain]] -> Gary@mcdok.com | E20: MCDOK | F20: Steven Vaughn | H20: =LEFT(Table1[[#This Row],[Supervisor]], SEARCH(" ", Table1[[#This Row],[Supervisor]]) - 1) & "@" & Table1[[#This Row],[Email Domain]] -> Steven@mcdok.com | I20: Hunter McKee | J20: =LEFT(Table1[[#This Row],[GM]], SEARCH(" ", Table1[[#This Row],[GM]]) - 1) & "@" & Table1[[#This Row],[Email Domain]] -> Hunter@mcdok.com | K20: mcdok.com | L20: 449 | M20: ="mcdok.mdp+"&Table1[[#This Row],[Location Name]]&"@gmail.com" -> mcdok.mdp+34222@gmail.com | N20: ="Mcdok.mdp"&Table1[[#This Row],[Location Name]] -> Mcdok.mdp34222 | O20: 34222 - HARRAH, OK | P20: 3115 S Harrah Rd, Harrah, OK, 73045, USA | Q20: Yes | R20: No | T20: Monday | U20: =_xlfn.XLOOKUP(Table1[[#This Row],[Location Name]],'Risk Profiles'!$A$18:$A$37,'Risk Profiles'!$B$18:$B$37) -> Low | V20: =_xlfn.XLOOKUP(Table1[[#This Row],[Location Name]],'Risk Profiles'!$A$18:$A$37,'Risk Profiles'!$C$18:$C$37) -> Within Normal range | W20: =_xlfn.XLOOKUP(Table1[[#This Row],[Location Name]],'Risk Profiles'!$A$18:$A$37,'Risk Profiles'!$D$18:$D$37) -> Medium | X20: =_xlfn.XLOOKUP(Table1[[#This Row],[Location Name]],'Risk Profiles'!$A$18:$A$37,'Risk Profiles'!$E$18:$E$37) -> High Discounts (6.58%) | Y20: Kaylee | Z20: Yes | AA20: =_xlfn.XLOOKUP(A20,Table3[Location],Table3[Date Scheduled]) -> 46162 | AB20: Monday | AC20: Thursday | AE20: 46129 | AF20: Lezli | AG20: 46239 | AH20: Yes | AI20: Yes | AJ20: Yes | AK20: =IFERROR(INDEX('Scheduling Setup'!$L:$L,MATCH($A20,'Scheduling Setup'!$A:$A,0)),"") -> 46246 | BA20: 5183 | BB20: =_xlfn.XLOOKUP($BA20,$A$3:$A$32,$F$3:$F$32) -> Krystiana Langford | BC20: =_xlfn.XLOOKUP($BA20,$A$3:$A$32,$I$3:$I$32) -> Mukarram Norman | BD20: =IF(_xlfn.XLOOKUP($BA20,$A$3:$A$32,$Y$3:$Y$32)="","",_xlfn.XLOOKUP($BA20,$A$3:$A$32,$Y$3:$Y$32)) -> Mukarram | BE20: 4-6 Hours | BF20: 46163 | BG20: 0.33333333 | BH20: =_xlfn.XLOOKUP(Table3[[#This Row],[Location]],Table4[STORE '#],Table4[DATE RGR]) -> 46281 | BI20: =_xlfn.XLOOKUP(Table3[[#This Row],[Location]],Table1[Location Name],Table1[Weekly Inventory Count Day]) -> Thursday | BJ20: =_xlfn.XLOOKUP(Table3[[#This Row],[Location]],Table1[Location Name],Table1[FOB Risk Profile]) -> Medium | BK20: Earliest available date | BL20: Changed from 04/23/26 | BM20: 46129
A21: 35064 | B21: Rick/Kathy Thorley | C21: rick@mcdok.com | D21: kathy@mcdok.com | E21: MCDOK | F21: Steven Vaughn | H21: =LEFT(Table1[[#This Row],[Supervisor]], SEARCH(" ", Table1[[#This Row],[Supervisor]]) - 1) & "@" & Table1[[#This Row],[Email Domain]] -> Steven@mcdok.com | I21: Lynsey Yahola | J21: =LEFT(Table1[[#This Row],[GM]], SEARCH(" ", Table1[[#This Row],[GM]]) - 1) & "@" & Table1[[#This Row],[Email Domain]] -> Lynsey@mcdok.com | K21: mcdok.com | L21: 452 | M21: ="mcdok.mdp+"&Table1[[#This Row],[Location Name]]&"@gmail.com" -> mcdok.mdp+35064@gmail.com | N21: ="Mcdok.mdp"&Table1[[#This Row],[Location Name]] -> Mcdok.mdp35064 | O21: 35064 - HOLDENVILLE, OK | P21: 424 E Highway St, Holdenville, OK, 74848, USA | Q21: Yes | R21: Yes | S21: 46106 | T21: Wednesday | U21: =_xlfn.XLOOKUP(Table1[[#This Row],[Location Name]],'Risk Profiles'!$A$18:$A$37,'Risk Profiles'!$B$18:$B$37) -> High | V21: =_xlfn.XLOOKUP(Table1[[#This Row],[Location Name]],'Risk Profiles'!$A$18:$A$37,'Risk Profiles'!$C$18:$C$37) -> High FOB% (6.12%), Stat Var (2.73%), Waste (1.40%) | W21: =_xlfn.XLOOKUP(Table1[[#This Row],[Location Name]],'Risk Profiles'!$A$18:$A$37,'Risk Profiles'!$D$18:$D$37) -> HIgh | X21: =_xlfn.XLOOKUP(Table1[[#This Row],[Location Name]],'Risk Profiles'!$A$18:$A$37,'Risk Profiles'!$E$18:$E$37) -> T-Red After (0.42%), Cash O/S (0.05%) | Y21: Lynsey | Z21: Yes | AA21: =_xlfn.XLOOKUP(A21,Table3[Location],Table3[Date Scheduled]) -> 46092 | AB21: Monday | AC21: Thursday | AE21: 46129 | AF21: Kevonte | AG21: 46246 | AH21: Yes | AI21: Yes | AJ21: Yes | AK21: =IFERROR(INDEX('Scheduling Setup'!$L:$L,MATCH($A21,'Scheduling Setup'!$A:$A,0)),"") -> 46253 | BA21: 33109 | BB21: =_xlfn.XLOOKUP($BA21,$A$3:$A$32,$F$3:$F$32) -> Ashley Podroza | BC21: =_xlfn.XLOOKUP($BA21,$A$3:$A$32,$I$3:$I$32) -> Rey Araiz | BD21: =IF(_xlfn.XLOOKUP($BA21,$A$3:$A$32,$Y$3:$Y$32)="","",_xlfn.XLOOKUP($BA21,$A$3:$A$32,$Y$3:$Y$32)) -> Gisselle | BE21: 4-6 Hours | BF21: 46170 | BG21: 0.33333333 | BH21: =_xlfn.XLOOKUP(Table3[[#This Row],[Location]],Table4[STORE '#],Table4[DATE RGR]) -> 46295 | BI21: =_xlfn.XLOOKUP(Table3[[#This Row],[Location]],Table1[Location Name],Table1[Weekly Inventory Count Day]) -> Tuesday | BJ21: =_xlfn.XLOOKUP(Table3[[#This Row],[Location]],Table1[Location Name],Table1[FOB Risk Profile]) -> Low | BK21: Earliest available date | BL21: Changed from 05/21/26 | BM21: 46129
A22: 43380 | B22: Ryan Thorley | C22: rick@mcdok.com | D22: kathy@mcdok.com | E22: MCDOK | F22: Ashley Podroza | H22: =LEFT(Table1[[#This Row],[Supervisor]], SEARCH(" ", Table1[[#This Row],[Supervisor]]) - 1) & "@" & Table1[[#This Row],[Email Domain]] -> Ashley@mcdok.com | I22: Zukarr Eaves | J22: =LEFT(Table1[[#This Row],[GM]], SEARCH(" ", Table1[[#This Row],[GM]]) - 1) & "@" & Table1[[#This Row],[Email Domain]] -> Zukarr@mcdok.com | K22: mcdok.com | L22: 249 | M22: ="mcdok.mdp+"&Table1[[#This Row],[Location Name]]&"@gmail.com" -> mcdok.mdp+43380@gmail.com | N22: ="Mcdok.mdp"&Table1[[#This Row],[Location Name]] -> Mcdok.mdp43380 | O22: 43380 - MAIN AND REFUGE-TISHOMINGO, OK | P22: 1309 E Main St, Tishomingo, OK, 73460, USA | Q22: Yes | R22: No | T22: Saturday | U22: =_xlfn.XLOOKUP(Table1[[#This Row],[Location Name]],'Risk Profiles'!$A$18:$A$37,'Risk Profiles'!$B$18:$B$37) -> Medium | V22: =_xlfn.XLOOKUP(Table1[[#This Row],[Location Name]],'Risk Profiles'!$A$18:$A$37,'Risk Profiles'!$C$18:$C$37) -> Within Normal range | W22: =_xlfn.XLOOKUP(Table1[[#This Row],[Location Name]],'Risk Profiles'!$A$18:$A$37,'Risk Profiles'!$D$18:$D$37) -> Medium | X22: =_xlfn.XLOOKUP(Table1[[#This Row],[Location Name]],'Risk Profiles'!$A$18:$A$37,'Risk Profiles'!$E$18:$E$37) -> T-Red After (0.38%), Cash O/S (0.05%), Overrings (0.38%) | Y22: Zukaar | Z22: Yes | AA22: =_xlfn.XLOOKUP(A22,Table3[Location],Table3[Date Scheduled]) -> 46088 | AB22: Tuesday | AC22: Friday | AE22: 46129 | AF22: Sabrina Turner | AG22: 46240 | AH22: Yes | AI22: Yes | AJ22: Yes | AK22: =IFERROR(INDEX('Scheduling Setup'!$L:$L,MATCH($A22,'Scheduling Setup'!$A:$A,0)),"") -> 46246 | BA22: 18213 | BB22: =_xlfn.XLOOKUP($BA22,$A$3:$A$32,$F$3:$F$32) -> Krystiana Langford | BC22: =_xlfn.XLOOKUP($BA22,$A$3:$A$32,$I$3:$I$32) -> Cora Bahling | BD22: =IF(_xlfn.XLOOKUP($BA22,$A$3:$A$32,$Y$3:$Y$32)="","",_xlfn.XLOOKUP($BA22,$A$3:$A$32,$Y$3:$Y$32)) -> Crystal | BE22: 4-6 Hours | BF22: 46177 | BG22: 0.33333333 | BH22: =_xlfn.XLOOKUP(Table3[[#This Row],[Location]],Table4[STORE '#],Table4[DATE RGR]) -> 46338 | BI22: =_xlfn.XLOOKUP(Table3[[#This Row],[Location]],Table1[Location Name],Table1[Weekly Inventory Count Day]) -> Thursday | BJ22: =_xlfn.XLOOKUP(Table3[[#This Row],[Location]],Table1[Location Name],Table1[FOB Risk Profile]) -> Medium | BK22: Earliest available date | BL22: Changed from 05/07/26 | BM22: 46129
A23: 6178 | B23: Jacob Thorley | C23: =LEFT(Table1[[#This Row],[Owner/Operator]], SEARCH(" ", Table1[[#This Row],[Owner/Operator]]) - 1) & "@" & Table1[[#This Row],[Email Domain]] -> Jacob@emeraldarches.com | E23: Emerald Arches | F23: Mary Ratliff | G23: 46225 | H23: =LEFT(Table1[[#This Row],[Supervisor]], SEARCH(" ", Table1[[#This Row],[Supervisor]]) - 1) & "@" & Table1[[#This Row],[Email Domain]] -> Mary@emeraldarches.com | I23: Janet Jeter | J23: =LEFT(Table1[[#This Row],[GM]], SEARCH(" ", Table1[[#This Row],[GM]]) - 1) & "@" & Table1[[#This Row],[Email Domain]] -> Janet@emeraldarches.com | K23: emeraldarches.com | L23: 472 | M23: ="mcdok.mdp+"&Table1[[#This Row],[Location Name]]&"@gmail.com" -> mcdok.mdp+6178@gmail.com | N23: ="Mcdok.mdp"&Table1[[#This Row],[Location Name]] -> Mcdok.mdp6178 | O23: 6178 - CHIPLEY-ST.RD.77 | P23: 1291 Main St, Chipley, FL, 32428, USA | U23: =_xlfn.XLOOKUP(Table1[[#This Row],[Location Name]],'Risk Profiles'!$A$18:$A$37,'Risk Profiles'!$B$18:$B$37) -> #N/A | V23: =_xlfn.XLOOKUP(Table1[[#This Row],[Location Name]],'Risk Profiles'!$A$18:$A$37,'Risk Profiles'!$C$18:$C$37) -> #N/A | W23: =_xlfn.XLOOKUP(Table1[[#This Row],[Location Name]],'Risk Profiles'!$A$18:$A$37,'Risk Profiles'!$D$18:$D$37) -> #N/A | X23: =_xlfn.XLOOKUP(Table1[[#This Row],[Location Name]],'Risk Profiles'!$A$18:$A$37,'Risk Profiles'!$E$18:$E$37) -> #N/A | AA23: =_xlfn.XLOOKUP(A23,Table3[Location],Table3[Date Scheduled]) -> #N/A | AK23: =IFERROR(INDEX('Scheduling Setup'!$L:$L,MATCH($A23,'Scheduling Setup'!$A:$A,0)),"")
A24: 6838 | B24: Jacob Thorley | C24: =LEFT(Table1[[#This Row],[Owner/Operator]], SEARCH(" ", Table1[[#This Row],[Owner/Operator]]) - 1) & "@" & Table1[[#This Row],[Email Domain]] -> Jacob@emeraldarches.com | E24: Emerald Arches | F24: Mary Ratliff | G24: 46225 | H24: =LEFT(Table1[[#This Row],[Supervisor]], SEARCH(" ", Table1[[#This Row],[Supervisor]]) - 1) & "@" & Table1[[#This Row],[Email Domain]] -> Mary@emeraldarches.com | I24: Stephanie Harris | J24: =LEFT(Table1[[#This Row],[GM]], SEARCH(" ", Table1[[#This Row],[GM]]) - 1) & "@" & Table1[[#This Row],[Email Domain]] -> Stephanie@emeraldarches.com | K24: emeraldarches.com | L24: 490 | M24: ="mcdok.mdp+"&Table1[[#This Row],[Location Name]]&"@gmail.com" -> mcdok.mdp+6838@gmail.com | N24: ="Mcdok.mdp"&Table1[[#This Row],[Location Name]] -> Mcdok.mdp6838 | O24: 6838 - DEFUNIAK SPRINGS | P24: 2370 US Highway 331 S, Defuniak Springs, FL, 32435, USA | U24: =_xlfn.XLOOKUP(Table1[[#This Row],[Location Name]],'Risk Profiles'!$A$18:$A$37,'Risk Profiles'!$B$18:$B$37) -> #N/A | V24: =_xlfn.XLOOKUP(Table1[[#This Row],[Location Name]],'Risk Profiles'!$A$18:$A$37,'Risk Profiles'!$C$18:$C$37) -> #N/A | W24: =_xlfn.XLOOKUP(Table1[[#This Row],[Location Name]],'Risk Profiles'!$A$18:$A$37,'Risk Profiles'!$D$18:$D$37) -> #N/A | X24: =_xlfn.XLOOKUP(Table1[[#This Row],[Location Name]],'Risk Profiles'!$A$18:$A$37,'Risk Profiles'!$E$18:$E$37) -> #N/A | AA24: =_xlfn.XLOOKUP(A24,Table3[Location],Table3[Date Scheduled]) -> #N/A | AK24: =IFERROR(INDEX('Scheduling Setup'!$L:$L,MATCH($A24,'Scheduling Setup'!$A:$A,0)),"")
A25: 10034 | B25: Ryan Thorley | C25: =LEFT(Table1[[#This Row],[Owner/Operator]], SEARCH(" ", Table1[[#This Row],[Owner/Operator]]) - 1) & "@" & Table1[[#This Row],[Email Domain]] -> Ryan@emeraldarches.com | E25: Emerald Arches | F25: Mary Ratliff | G25: 46225 | H25: =LEFT(Table1[[#This Row],[Supervisor]], SEARCH(" ", Table1[[#This Row],[Supervisor]]) - 1) & "@" & Table1[[#This Row],[Email Domain]] -> Mary@emeraldarches.com | I25: Harlee Yates | J25: =LEFT(Table1[[#This Row],[GM]], SEARCH(" ", Table1[[#This Row],[GM]]) - 1) & "@" & Table1[[#This Row],[Email Domain]] -> Harlee@emeraldarches.com | K25: emeraldarches.com | L25: 483 | M25: ="mcdok.mdp+"&Table1[[#This Row],[Location Name]]&"@gmail.com" -> mcdok.mdp+10034@gmail.com | N25: ="Mcdok.mdp"&Table1[[#This Row],[Location Name]] -> Mcdok.mdp10034 | O25: 10034 - BONIFAY | P25: 2010 S Waukesha St, Bonifay, FL, 32425, USA | U25: =_xlfn.XLOOKUP(Table1[[#This Row],[Location Name]],'Risk Profiles'!$A$18:$A$37,'Risk Profiles'!$B$18:$B$37) -> #N/A | V25: =_xlfn.XLOOKUP(Table1[[#This Row],[Location Name]],'Risk Profiles'!$A$18:$A$37,'Risk Profiles'!$C$18:$C$37) -> #N/A | W25: =_xlfn.XLOOKUP(Table1[[#This Row],[Location Name]],'Risk Profiles'!$A$18:$A$37,'Risk Profiles'!$D$18:$D$37) -> #N/A | X25: =_xlfn.XLOOKUP(Table1[[#This Row],[Location Name]],'Risk Profiles'!$A$18:$A$37,'Risk Profiles'!$E$18:$E$37) -> #N/A | AA25: =_xlfn.XLOOKUP(A25,Table3[Location],Table3[Date Scheduled]) -> #N/A | AK25: =IFERROR(INDEX('Scheduling Setup'!$L:$L,MATCH($A25,'Scheduling Setup'!$A:$A,0)),"")
A26: 35242 | B26: Jacob Thorley | C26: =LEFT(Table1[[#This Row],[Owner/Operator]], SEARCH(" ", Table1[[#This Row],[Owner/Operator]]) - 1) & "@" & Table1[[#This Row],[Email Domain]] -> Jacob@emeraldarches.com | E26: Emerald Arches | F26: Brad Denley | H26: =LEFT(Table1[[#This Row],[Supervisor]], SEARCH(" ", Table1[[#This Row],[Supervisor]]) - 1) & "@" & Table1[[#This Row],[Email Domain]] -> Brad@emeraldarches.com | I26: Michele Nixon | J26: =LEFT(Table1[[#This Row],[GM]], SEARCH(" ", Table1[[#This Row],[GM]]) - 1) & "@" & Table1[[#This Row],[Email Domain]] -> Michele@emeraldarches.com | K26: emeraldarches.com | L26: 469 | M26: ="mcdok.mdp+"&Table1[[#This Row],[Location Name]]&"@gmail.com" -> mcdok.mdp+35242@gmail.com | N26: ="Mcdok.mdp"&Table1[[#This Row],[Location Name]] -> Mcdok.mdp35242 | O26: 35242 - COTTONDALE | P26: 2510 Highway 231, Cottondale, FL, 32431, USA | U26: =_xlfn.XLOOKUP(Table1[[#This Row],[Location Name]],'Risk Profiles'!$A$18:$A$37,'Risk Profiles'!$B$18:$B$37) -> #N/A | V26: =_xlfn.XLOOKUP(Table1[[#This Row],[Location Name]],'Risk Profiles'!$A$18:$A$37,'Risk Profiles'!$C$18:$C$37) -> #N/A | W26: =_xlfn.XLOOKUP(Table1[[#This Row],[Location Name]],'Risk Profiles'!$A$18:$A$37,'Risk Profiles'!$D$18:$D$37) -> #N/A | X26: =_xlfn.XLOOKUP(Table1[[#This Row],[Location Name]],'Risk Profiles'!$A$18:$A$37,'Risk Profiles'!$E$18:$E$37) -> #N/A | AA26: =_xlfn.XLOOKUP(A26,Table3[Location],Table3[Date Scheduled]) -> #N/A | AK26: =IFERROR(INDEX('Scheduling Setup'!$L:$L,MATCH($A26,'Scheduling Setup'!$A:$A,0)),"")
A27: 37566 | B27: Ryan Thorley | C27: =LEFT(Table1[[#This Row],[Owner/Operator]], SEARCH(" ", Table1[[#This Row],[Owner/Operator]]) - 1) & "@" & Table1[[#This Row],[Email Domain]] -> Ryan@emeraldarches.com | E27: Emerald Arches | F27: Mary Ratliff | G27: 46225 | H27: =LEFT(Table1[[#This Row],[Supervisor]], SEARCH(" ", Table1[[#This Row],[Supervisor]]) - 1) & "@" & Table1[[#This Row],[Email Domain]] -> Mary@emeraldarches.com | I27: Debra Herndon | J27: =LEFT(Table1[[#This Row],[GM]], SEARCH(" ", Table1[[#This Row],[GM]]) - 1) & "@" & Table1[[#This Row],[Email Domain]] -> Debra@emeraldarches.com | K27: emeraldarches.com | L27: 484 | M27: ="mcdok.mdp+"&Table1[[#This Row],[Location Name]]&"@gmail.com" -> mcdok.mdp+37566@gmail.com | N27: ="Mcdok.mdp"&Table1[[#This Row],[Location Name]] -> Mcdok.mdp37566 | O27: 37566 - MOSSY HEAD | P27: 17750 State Highway 285 Dr S, Defuniak Springs, FL, 32435, USA | U27: =_xlfn.XLOOKUP(Table1[[#This Row],[Location Name]],'Risk Profiles'!$A$18:$A$37,'Risk Profiles'!$B$18:$B$37) -> #N/A | V27: =_xlfn.XLOOKUP(Table1[[#This Row],[Location Name]],'Risk Profiles'!$A$18:$A$37,'Risk Profiles'!$C$18:$C$37) -> #N/A | W27: =_xlfn.XLOOKUP(Table1[[#This Row],[Location Name]],'Risk Profiles'!$A$18:$A$37,'Risk Profiles'!$D$18:$D$37) -> #N/A | X27: =_xlfn.XLOOKUP(Table1[[#This Row],[Location Name]],'Risk Profiles'!$A$18:$A$37,'Risk Profiles'!$E$18:$E$37) -> #N/A | AA27: =_xlfn.XLOOKUP(A27,Table3[Location],Table3[Date Scheduled]) -> #N/A | AK27: =IFERROR(INDEX('Scheduling Setup'!$L:$L,MATCH($A27,'Scheduling Setup'!$A:$A,0)),"")
A28: 38609 | B28: Jacob Thorley | C28: =LEFT(Table1[[#This Row],[Owner/Operator]], SEARCH(" ", Table1[[#This Row],[Owner/Operator]]) - 1) & "@" & Table1[[#This Row],[Email Domain]] -> Jacob@emeraldarches.com | E28: Emerald Arches | F28: Brad Denley | H28: =LEFT(Table1[[#This Row],[Supervisor]], SEARCH(" ", Table1[[#This Row],[Supervisor]]) - 1) & "@" & Table1[[#This Row],[Email Domain]] -> Brad@emeraldarches.com | I28: Christina Bencokzy | J28: =LEFT(Table1[[#This Row],[GM]], SEARCH(" ", Table1[[#This Row],[GM]]) - 1) & "@" & Table1[[#This Row],[Email Domain]] -> Christina@emeraldarches.com | K28: emeraldarches.com | L28: 467 | M28: ="mcdok.mdp+"&Table1[[#This Row],[Location Name]]&"@gmail.com" -> mcdok.mdp+38609@gmail.com | N28: ="Mcdok.mdp"&Table1[[#This Row],[Location Name]] -> Mcdok.mdp38609 | O28: 38609 - FREEPORT | P28: 16392 US Highway 331 S, Freeport, FL, 32439, USA | U28: =_xlfn.XLOOKUP(Table1[[#This Row],[Location Name]],'Risk Profiles'!$A$18:$A$37,'Risk Profiles'!$B$18:$B$37) -> #N/A | V28: =_xlfn.XLOOKUP(Table1[[#This Row],[Location Name]],'Risk Profiles'!$A$18:$A$37,'Risk Profiles'!$C$18:$C$37) -> #N/A | W28: =_xlfn.XLOOKUP(Table1[[#This Row],[Location Name]],'Risk Profiles'!$A$18:$A$37,'Risk Profiles'!$D$18:$D$37) -> #N/A | X28: =_xlfn.XLOOKUP(Table1[[#This Row],[Location Name]],'Risk Profiles'!$A$18:$A$37,'Risk Profiles'!$E$18:$E$37) -> #N/A | AA28: =_xlfn.XLOOKUP(A28,Table3[Location],Table3[Date Scheduled]) -> #N/A | AK28: =IFERROR(INDEX('Scheduling Setup'!$L:$L,MATCH($A28,'Scheduling Setup'!$A:$A,0)),"")
A29: 43701 | B29: Ryan Thorley | C29: =LEFT(Table1[[#This Row],[Owner/Operator]], SEARCH(" ", Table1[[#This Row],[Owner/Operator]]) - 1) & "@" & Table1[[#This Row],[Email Domain]] -> Ryan@emeraldarches.com | E29: Emerald Arches | F29: Brad Denley | H29: =LEFT(Table1[[#This Row],[Supervisor]], SEARCH(" ", Table1[[#This Row],[Supervisor]]) - 1) & "@" & Table1[[#This Row],[Email Domain]] -> Brad@emeraldarches.com | I29: Shannon Hardin | J29: =LEFT(Table1[[#This Row],[GM]], SEARCH(" ", Table1[[#This Row],[GM]]) - 1) & "@" & Table1[[#This Row],[Email Domain]] -> Shannon@emeraldarches.com | K29: emeraldarches.com | L29: 1523 | M29: ="mcdok.mdp+"&Table1[[#This Row],[Location Name]]&"@gmail.com" -> mcdok.mdp+43701@gmail.com | N29: ="Mcdok.mdp"&Table1[[#This Row],[Location Name]] -> Mcdok.mdp43701 | O29: 43701 - HWY 81 AND I-10-PONCE DE LEON, FL | P29: 2920 FL-81, Ponce de Leon, FL, 32455, USA | U29: =_xlfn.XLOOKUP(Table1[[#This Row],[Location Name]],'Risk Profiles'!$A$18:$A$37,'Risk Profiles'!$B$18:$B$37) -> #N/A | V29: =_xlfn.XLOOKUP(Table1[[#This Row],[Location Name]],'Risk Profiles'!$A$18:$A$37,'Risk Profiles'!$C$18:$C$37) -> #N/A | W29: =_xlfn.XLOOKUP(Table1[[#This Row],[Location Name]],'Risk Profiles'!$A$18:$A$37,'Risk Profiles'!$D$18:$D$37) -> #N/A | X29: =_xlfn.XLOOKUP(Table1[[#This Row],[Location Name]],'Risk Profiles'!$A$18:$A$37,'Risk Profiles'!$E$18:$E$37) -> #N/A | AA29: =_xlfn.XLOOKUP(A29,Table3[Location],Table3[Date Scheduled]) -> #N/A | AK29: =IFERROR(INDEX('Scheduling Setup'!$L:$L,MATCH($A29,'Scheduling Setup'!$A:$A,0)),"")
